Workbook
Name Season: #REF!

Sheet simulator
B1: Enter Ratings for both teams | H1: Enter info into all light yellow cells | P1: Win A | Q1: Draw | R1: Win B | X1: =B15 -> Team A | AD1: =B19 -> Team B
B2: Enter via match ratings (blue) or sector percentages (green) | H2: Grey cells are informational | O2: After 90': | P2: =+S38 -> 0.69244254 | Q2: =+T38 -> 0.19099163 | R2: =+U38 -> 0.11656583 | T2: Normal Chances: | U2: 10 | W2: Chance after Poss: | X2: =U3*IF($D$4="Percent",C7,C11) -> 8 | Y2: % CA: | Z2: =VLOOKUP(IF(OR(C11>=0.5,AA31=0),COUNTA($I$13:$M$13)&"D",AA31),lkup_simul!$BH:$BI,2,FALSE)+VLOOKUP(COUNTIF($I$13:$M$13,"T"),lkup_simul!$GI$2:$GM$7,5,FALSE) -> 0.04328233 | AC2: Chance after Poss | AD2: =U3*IF($D$4="Percent",C8,C12) -> 2 | AE2: % CA: | AF2: =VLOOKUP(IF(OR(C12>=0.5,AB31=0),COUNTA($I$19:$M$19)&"D",AB31),lkup_simul!$BH:$BI,2,FALSE)+VLOOKUP(COUNTIF($I$19:$M$19,"T"),lkup_simul!$GI$2:$GM$7,5,FALSE) -> 0.036575107 | AN2: 3.5 | AO2: =+IF(AND(AA33>0,AB33=0),4,IF(AND(AB33>0,AA33=0),2.5,3.5)) -> 2.5 | AP2: =+IF(AO2=4,2.5,IF(AO2=2.5,4,3.5)) -> 4
B3: Rater will use the input selected below | H3: Enter specialties below ("Yes") or choose to skip this step ("No") | P3: =+P2/(P2+R2) -> 0.85591518 | Q3: Win Reg | R3: =1-P3 -> 0.14408482 | T3: Chance after Press: | U3: =U2-VLOOKUP(AA34,lkup_simul!$G:$H,2,FALSE)-VLOOKUP(AB34,lkup_simul!$G:$H,2,FALSE) -> 10 | W3: Chance after PDIM: | X3: =X2*(1-VLOOKUP(AB17,lkup_simul!$D$8:$E$11,2,FALSE)) -> 8 | Y3: U CAs: | Z3: =0.05*(SUM(AP11:AP12)-SUM(AT11:AT12)) -> 0.015404291 | AC3: Chance after PDIM | AD3: =AD2*(1-VLOOKUP(AA17,lkup_simul!$D$8:$E$11,2,FALSE)) -> 1.8706937 | AE3: U CAs: | AF3: =0.05*(SUM(AO11:AO12)-SUM(AS11:AS12)) -> 0 | AN3: PC factor | AO3: =+VLOOKUP(AH33,lkup_simul!$AA:$AI,8,TRUE)*AI33 -> 2.05 | BE3: Attacker | BF3: Defender (100%) | BG3: Defender (25%)
B4: Ratings input: | D4: Percent | H4: Specialties input: | J4: Yes | O4: After 120': | P4: =+P2+(Q2-Q4)*P3 -> 0.78261498 | Q4: =+VLOOKUP(AVERAGE(P7,R7),lkup_simul!$GX$7:$GY$19,2,TRUE)*VLOOKUP(ABS(P7-R7),lkup_simul!$HA$7:$HB$28,2,TRUE)*Q2 -> 0.085639556 | R4: =+R2+(Q2-Q4)*R3 -> 0.13174546 | W4: Press LS%: | X4: =VLOOKUP(AA32,lkup_simul!$FP:$FQ,2,TRUE)*VLOOKUP(AB34,lkup_simul!$FS:$FT,2,TRUE) -> 0 | Y4: CAs: | Z4: =AB16*Z2+Z3 -> 0.094409141 | AC4: Press LS%: | AD4: =VLOOKUP(AB32,lkup_simul!$FP:$FQ,2,TRUE)*VLOOKUP(AA34,lkup_simul!$FS:$FT,2,TRUE) -> 0 | AE4: CAs: | AF4: =AA16*AF2 -> 0.23527852 | AI4: Triggers | AJ4: Event | AK4: Freq | AL4: Players A | AM4: Players B | AN4: % Event A | AO4: Freq A | AP4: Freq B | AQ4: Conv A | AR4: Conv B | AS4: xG A | AT4: xG B | AU4: WI-H A | AV4: WI-H B | AW4: A | AX4: Spec | AY4: hlookup | BA4: HTS_Calc | BB4: Team A | BC4: Team B | BE4: W Right, FW Right | BF4: WB Left | BG4: CD Left
P5: =+IF(J7>J8,VLOOKUP(ABS(J7-J8)*4,lkup_simul!$HD:$HE,2,TRUE),1-VLOOKUP(ABS(J7-J8)*4,lkup_simul!$HD:$HE,2,TRUE)) -> 0.59909763 | Q5: Win PK | R5: =1-P5 -> 0.40090237 | V5: Type: | W5: Normal | X5: Normal | Y5: Normal | Z5: CA / PNF | AA5: CA / PNF | AC5: Normal | AD5: Normal | AE5: Normal | AF5: CA / PNF | AG5: CA / PNF | AI5: Offensive | AJ5: Q Rush | AK5: 0.0871 | AL5: =COUNTIF($I$11:$M$12,"Q") -> 3 | AM5: =COUNTIF($I$17:$M$18,"Q") -> 3 | AN5: =+IFERROR(IF(AL5=AM5,AW5,(AL5^$AW5)/(AL5^$AW5+AM5^$AW5)),0) -> 0.42857143 | AO5: =+AK5*VLOOKUP(MAX(AL5,AM5),lkup_simul!$DP:$DT,4,FALSE)*AN5*AO$3 -> 0.21625561 | AP5: =+AK5*VLOOKUP(MAX(AL5,AM5),lkup_simul!$DP:$DT,4,FALSE)*(1-AN5)*AO$3 -> 0.28834082 | AQ5: =HLOOKUP($K$8,conv_Kstars!$CB$6:$CY$27,$AY5,FALSE)*AO33 -> 0.2908805 | AR5: =HLOOKUP($K$7,conv_Kstars!$CB$6:$CY$27,$AY5,FALSE)*AO36 -> 0.28 | AS5: =+IFERROR(AO5*AQ5,0) -> 0.062904541 | AT5: =+IFERROR(AP5*AR5,0) -> 0.080735429 | AW5: =+IF($AO$2=4,IF(AL5=AM5,(AL5+1)/(AL5+1+AM5),IF(AL5>AM5,$AO$2,$AP$2)),IF($AO$2=2.5,IF(AL5=AM5,(AL5)/(AL5+1+AM5),IF(AL5>AM5,$AO$2,$AP$2)),IF($AO$2=3.5,IF(AL5=AM5,0.5,3.5)))) -> 0.42857143 | AX5: Q | AY5: 7 | BA5: Att | BB5: =+BE12*D14+BF12*E14+BE12*F14 -> 13.575 | BC5: =+BE12*D18+BF12*E18+BE12*F18 -> 13 | BE5: W Left, FW Left | BF5: WB Right | BG5: CD Right
B6: Percent | C6: MF | D6: Left | E6: Center | F6: Right | I6: ISP Def | J6: ISP Att | K6: GK Stars | L6: Tac Level | M6: Tactic | O6: After PK': | P6: =+P2+Q2*P46 -> 0.69244254 | Q6: After PK | R6: =+R2+Q2*R46 -> 0.11656583 | T6: Dist | U6: Sector | V6: %conv | W6: %dist | X6: chances | Y6: goals | Z6: chances | AA6: goals | AB6: %conv | AC6: %dist | AD6: chances | AE6: goals | AF6: chances | AG6: goals | AI6: Offensive | AJ6: Q Pass | AK6: 0.0815 | AL6: =COUNTIF($I$11:$M$12,"Q") -> 3 | AM6: =COUNTIF($I$17:$M$18,"Q") -> 3 | AN6: =+IFERROR(IF(AL6=AM6,AW6,(AL6^$AW6)/(AL6^$AW6+AM6^$AW6)),0) -> 0.42857143 | AO6: =+AK6*VLOOKUP(MAX(AL6,AM6),lkup_simul!$DP:$DT,4,FALSE)*AN6*AO$3 -> 0.20235169 | AP6: =+AK6*VLOOKUP(MAX(AL6,AM6),lkup_simul!$DP:$DT,4,FALSE)*(1-AN6)*AO$3 -> 0.26980226 | AQ6: =HLOOKUP($K$8,conv_Kstars!$CB$6:$CY$27,$AY6,FALSE)*AO33 -> 0.35949761 | AR6: =HLOOKUP($K$7,conv_Kstars!$CB$6:$CY$27,$AY6,FALSE)*AO36 -> 0.35449761 | AS6: =+IFERROR(AO6*AQ6,0) -> 0.072744949 | AT6: =+IFERROR(AP6*AR6,0) -> 0.095644255 | AW6: =+IF($AO$2=4,IF(AL6=AM6,(AL6+1)/(AL6+1+AM6),IF(AL6>AM6,$AO$2,$AP$2)),IF($AO$2=2.5,IF(AL6=AM6,(AL6)/(AL6+1+AM6),IF(AL6>AM6,$AO$2,$AP$2)),IF($AO$2=3.5,IF(AL6=AM6,0.5,3.5)))) -> 0.42857143 | AX6: Q | AY6: 6 | BA6: Def | BB6: =+BE13*D16+BF13*E16+BE13*F16 -> 15.7 | BC6: =+BE13*D20+BF13*E20+BE13*F20 -> 15.15 | BE6: IM Right | BF6: CD Left | BG6: CD Middle, WB Left
B7: Team A: | C7: 0.8 | D7: 0.2 | E7: 0.2 | F7: 0.2 | H7: Team A: | I7: 12.5 | J7: 9.25 | K7: 10.5 | M7: (no tactic) | P7: =P18 -> 2.0913468 | Q7: xG | R7: =R18 -> 0.71968398 | T7: 0.259 | U7: Left | V7: =IF($D$4="Percent",D7,D11) -> 0.2 | W7: =(1-W13)*(T7*(1-AA20)+AA21/2*T8) -> 0.257446 | X7: =X$3*W7 -> 2.059568 | Y7: =X7*V7 -> 0.4119136 | Z7: =Z$4*T7 -> 0.024451967 | AA7: =Z7*V7 -> 0.0048903935 | AB7: =IF($D$4="Percent",D8,D12) -> 0.01 | AC7: =(1-AC13)*(T7*(1-AB20)+AB21/2*T8) -> 0.257446 | AD7: =AD$3*AC7 -> 0.48160261 | AE7: =AD7*AB7 -> 0.0048160261 | AF7: =$AF$4*T7 -> 0.060937138 | AG7: =AF7*AB7 -> 0.00060937138 | AI7: C-H Off: All but SP & K | AJ7: C-H A | AK7: 0.05 | AL7: =COUNTIF($I$11:$M$13,"H") -> 1 | AM7: =COUNTIF($I$17:$M$20,"H")+COUNTIF($I$17:$M$20,"H+SP") -> 0 | AN7: =AN15 -> 0.61351179 | AO7: =+AK7*VLOOKUP(AL7,lkup_simul!$DP:$DT,5,FALSE)*AN7*AO$3 -> 0.062884959 | AQ7: =VLOOKUP((J7-I8)*4,lkup_simul!$DH:$DI,2,TRUE)*VLOOKUP(AL7-AM7,lkup_simul!$DA:$DB,2,TRUE) -> 0.6028735 | AS7: =+IFERROR(AO7*AQ7,0) -> 0.037911675 | AX7: H | BA7: Tac | BB7: =+IF(AA32>0,8,IF(AA31>0,2,9)) -> 9 | BC7: =+IF(AB32>0,8,IF(AB31>0,2,9)) -> 9 | BE7: IM Left | BF7: CD Right | BG7: CD Middle, WB Right
B8: Team B: | C8: =1-C7 -> 0.2 | D8: 0.01 | E8: 0.01 | F8: 0.01 | H8: Team B: | I8: 12 | J8: 8.5 | K8: 10 | L8: 26 | M8: Play Creatively | P8: =+P2*3+Q2*1 -> 2.2683193 | Q8: xP | R8: =+R2*3+Q2 -> 0.54068911 | T8: 0.357 | U8: Center | V8: =IF($D$4="Percent",E7,E11) -> 0.2 | W8: =(1-W13)*(T8*(1-AA21)+AA20*T7*2) -> 0.354858 | X8: =X$3*W8 -> 2.838864 | Y8: =X8*V8 -> 0.5677728 | Z8: =Z$4*T8 -> 0.033704063 | AA8: =Z8*V8 -> 0.0067408127 | AB8: =IF($D$4="Percent",E8,E12) -> 0.01 | AC8: =(1-AC13)*(T8*(1-AB21)+AB20*T7*2) -> 0.354858 | AD8: =AD$3*AC8 -> 0.66383062 | AE8: =AD8*AB8 -> 0.0066383062 | AF8: =$AF$4*T8 -> 0.083994433 | AG8: =AF8*AB8 -> 0.00083994433 | AI8: C-H Def: All (incl K) | AJ8: C-H B | AK8: 0.05 | AL8: =COUNTIF($I$11:$M$14,"H")+COUNTIF($I$11:$M$14,"H+SP") -> 1 | AM8: =COUNTIF($I$17:$M$19,"H") -> 0 | AP8: =+AK8*VLOOKUP(AM8,lkup_simul!$DP:$DT,5,FALSE)*(1-AN7)*AO$3 -> 0 | AR8: =VLOOKUP((J8-I7)*4,lkup_simul!$DH:$DI,2,TRUE)*VLOOKUP(AM8-AL8,lkup_simul!$DA:$DB,2,TRUE) -> 0.2274375 | AT8: =+IFERROR(AP8*AR8,0) -> 0 | AW8: =+IF($AO$2=4,IF(AL8=AM8,(AL8+1)/(AL8+1+AM8),IF(AL8>AM8,$AO$2,$AP$2)),IF($AO$2=2.5,IF(AL8=AM8,(AL8)/(AL8+1+AM8),IF(AL8>AM8,$AO$2,$AP$2)),IF($AO$2=3.5,IF(AL8=AM8,0.5,3.5)))) -> 2.5 | AX8: H | BA8: TacMid | BB8: =IF(AND(BB7=2,E15/E19<0.5),3,BB7) -> 9 | BC8: =IF(AND(BC7=2,E19/E15<0.5),3,BC7) -> 9 | BE8: FW Middle, IM Middle | BF8: CD Middle | BG8: CD Left, CD Right
P9: =BB13 -> 293.30403 | Q9: HTS | R9: =BC13 -> 345.05154 | T9: 0.259 | U9: Right | V9: =IF($D$4="Percent",F7,F11) -> 0.2 | W9: =W7 -> 0.257446 | X9: =X$3*W9 -> 2.059568 | Y9: =X9*V9 -> 0.4119136 | Z9: =Z$4*T9 -> 0.024451967 | AA9: =Z9*V9 -> 0.0048903935 | AB9: =IF($D$4="Percent",F8,F12) -> 0.01 | AC9: =AC7 -> 0.257446 | AD9: =AD$3*AC9 -> 0.48160261 | AE9: =AD9*AB9 -> 0.0048160261 | AF9: =$AF$4*T9 -> 0.060937138 | AG9: =AF9*AB9 -> 0.00060937138 | AI9: Offensive | AJ9: W-H | AK9: 0.0509 | AL9: =COUNTIF($I$11:$M$12,"H")+COUNTIF($I$11:$M$12,"H+SP") -> 1 | AM9: =COUNTIF($I$17:$M$18,"H")+COUNTIF($I$17:$M$18,"H+SP") -> 0 | AN9: =+IFERROR(IF(AL9=AM9,AW9,(AL9^$AW9)/(AL9^$AW9+AM9^$AW9)),0) -> 1 | AO9: =+AK9*VLOOKUP(MAX(AL9,AM9),lkup_simul!$DP:$DT,4,FALSE)*AN9*AO$3*IF(AL9*AU9=1,0.5,1) -> 0.0521725 | AP9: =+AK9*VLOOKUP(MAX(AL9,AM9),lkup_simul!$DP:$DT,4,FALSE)*(1-AN9)*AO$3*IF(AM9*AV9=1,0.5,1) -> 0 | AQ9: =HLOOKUP($K$8,conv_Kstars!$CB$6:$CY$27,$AY9,FALSE) -> 0.48 | AR9: =HLOOKUP($K$7,conv_Kstars!$CB$6:$CY$27,$AY9,FALSE) -> 0.47 | AS9: =+IFERROR(AO9*AQ9,0) -> 0.0250428 | AT9: =+IFERROR(AP9*AR9,0) -> 0 | AU9: =COUNTIF(I12,"H")+COUNTIF(M12,"H") -> 1 | AV9: =COUNTIF(I18,"H")+COUNTIF(M18,"H") -> 0 | AW9: =+IF($AO$2=4,IF(AL9=AM9,(AL9+1)/(AL9+1+AM9),IF(AL9>AM9,$AO$2,$AP$2)),IF($AO$2=2.5,IF(AL9=AM9,(AL9)/(AL9+1+AM9),IF(AL9>AM9,$AO$2,$AP$2)),IF($AO$2=3.5,IF(AL9=AM9,0.5,3.5)))) -> 2.5 | AX9: H | AY9: 17 | BA9: Att | BB9: =+VLOOKUP(BB$7*1000+FLOOR(BB5*4-3,1),hts_calculator!$D:$E,2,FALSE) -> 1.2780399 | BC9: =+VLOOKUP(BC$7*1000+FLOOR(BC5*4-3,1),hts_calculator!$D:$E,2,FALSE) -> 1.2503803
B10: Ratings | C10: MF | D10: Left | E10: Center | F10: Right | K10: Team A | P10: =B15 -> Team A | R10: =B19 -> Team B | T10: 0.084 | U10: DFK | V10: =VLOOKUP(J$7,dfk_pk!$A$8:$AS$19,HLOOKUP(I$8,dfk_pk!$D$4:$O$5,2,TRUE)+15,TRUE) -> 0.12 | W10: =(1-W13)*T10*(1-AA22) -> 0.06011712 | X10: =X$3*W10 -> 0.48093696 | Y10: =X10*V10 -> 0.057712435 | Z10: =Z$4*T10*(1-AA22) -> 0.0057098648 | AA10: =Z10*V10 -> 0.00068518378 | AB10: =VLOOKUP(J$8,dfk_pk!$A$8:$AS$19,HLOOKUP(I$7,dfk_pk!$D$4:$O$5,2,TRUE)+15,TRUE) -> 0.08 | AC10: =(1-AC13)*T10*(1-AB22) -> 0.06095208 | AD10: =AD$3*AC10 -> 0.11402267 | AE10: =AD10*AB10 -> 0.0091218137 | AF10: =$AF$4*T10*(1-AB22) -> 0.014427279 | AG10: =AF10*AB10 -> 0.0011541823 | AI10: Def + K | AJ10: ULP | AK10: 0.0703 | AL10: =COUNTIF($I$13:$M$14,"U") -> 0 | AM10: =COUNTIF($I$19:$M$20,"U") -> 2 | AN10: =+IFERROR(IF(AL10=AM10,AW10,(AL10^$AW10)/(AL10^$AW10+AM10^$AW10)),0) -> 0 | AO10: =+AK10*VLOOKUP(MAX(AL10,AM10),lkup_simul!$DP:$DT,4,FALSE)*AN10*AO$3 -> 0 | AP10: =+AK10*VLOOKUP(MAX(AL10,AM10),lkup_simul!$DP:$DT,4,FALSE)*(1-AN10)*AO$3 -> 0.27871841 | AQ10: =HLOOKUP($K$8,conv_Kstars!$CB$6:$CY$27,$AY10,FALSE) -> 0.3064877 | AR10: =HLOOKUP($K$7,conv_Kstars!$CB$6:$CY$27,$AY10,FALSE) -> 0.30331754 | AS10: =+IFERROR(AO10*AQ10,0) -> 0 | AT10: =+IFERROR(AP10*AR10,0) -> 0.084540181 | AW10: =+IF($AO$2=4,IF(AL10=AM10,(AL10+1)/(AL10+1+AM10),IF(AL10>AM10,$AO$2,$AP$2)),IF($AO$2=2.5,IF(AL10=AM10,(AL10)/(AL10+1+AM10),IF(AL10>AM10,$AO$2,$AP$2)),IF($AO$2=3.5,IF(AL10=AM10,0.5,3.5)))) -> 4 | AX10: U | AY10: 11 | BA10: Mid | BB10: =+VLOOKUP(BB$8*1000+FLOOR(E15*4-3,1),hts_calculator!$G:$H,2,FALSE) -> 1.7386 | BC10: =+VLOOKUP(BC$8*1000+FLOOR(E19*4-3,1),hts_calculator!$G:$H,2,FALSE) -> 2.1293
B11: Team A: | C11: =+X26^3/(X26^3+AD26^3) -> 0.36120664 | D11: =+W25^3.5/(W25^3.5+AE27^3.5)*0.92 -> 0.40713839 | E11: =+X25^3.5/(X25^3.5+AD27^3.5)*0.92 -> 0.23707948 | F11: =+Y25^3.5/(Y25^3.5+AC27^3.5)*0.92 -> 0.54533308 | H11: FW | J11: PNF | L11: Q | P11: =SUM(P12:P17) -> 9.3908633 | Q11: Chances | R11: =SUM(R12:R17) -> 3.9399562 | U11: PK | V11: =VLOOKUP(J$7,dfk_pk!$A$8:$AS$19,HLOOKUP(I$8,dfk_pk!$D$4:$O$5,2,TRUE)+0,TRUE) -> 0.4 | W11: =(1-W13)*T10*AA22 -> 0.02337888 | X11: =X$3*W11 -> 0.18703104 | Y11: =X11*V11 -> 0.074812416 | Z11: =Z$4*T10*AA22 -> 0.002220503 | AA11: =Z11*V11 -> 0.0008882012 | AB11: =VLOOKUP(J$8,dfk_pk!$A$8:$AS$19,HLOOKUP(I$7,dfk_pk!$D$4:$O$5,2,TRUE)+0,TRUE) -> 0.36 | AC11: =(1-AC13)*T10*AB22 -> 0.02254392 | AD11: =AD$3*AC11 -> 0.042172769 | AE11: =AD11*AB11 -> 0.015182197 | AF11: =$AF$4*T10*AB22 -> 0.0053361169 | AG11: =AF11*AB11 -> 0.0019210021 | AI11: All but K | AJ11: U special | AK11: 0.0301 | AL11: =COUNTIF($I$11:$M$13,"U") -> 0 | AM11: =COUNTIF($I$17:$M$19,"U") -> 5 | AN11: =+IFERROR(IF(AL11=AM11,AW11,(AL11^$AW11)/(AL11^$AW11+AM11^$AW11)),0) -> 0 | AO11: =+AK11*VLOOKUP(MAX(AL11,AM11),lkup_simul!$DP:$DT,4,FALSE)*AN11*AO$3 -> 0 | AP11: =+AK11*VLOOKUP(MAX(AL11,AM11),lkup_simul!$DP:$DT,4,FALSE)*(1-AN11)*AO$3 -> 0.27952365 | AQ11: =HLOOKUP($K$8,conv_Kstars!$CB$6:$CY$27,$AY11,FALSE) -> 0.36560292 | AR11: =HLOOKUP($K$7,conv_Kstars!$CB$6:$CY$27,$AY11,FALSE) -> 0.35714286 | AS11: =+IFERROR(AO11*AQ11,0) -> 0 | AT11: =+IFERROR(AP11*AR11,0) -> 0.099829875 | AW11: =+IF($AO$2=4,IF(AL11=AM11,(AL11+1)/(AL11+1+AM11),IF(AL11>AM11,$AO$2,$AP$2)),IF($AO$2=2.5,IF(AL11=AM11,(AL11)/(AL11+1+AM11),IF(AL11>AM11,$AO$2,$AP$2)),IF($AO$2=3.5,IF(AL11=AM11,0.5,3.5)))) -> 4 | AX11: U | AY11: 15 | BA11: Def | BB11: =+VLOOKUP(BB$7*1000+FLOOR(BB6*4-3,1),hts_calculator!$A:$B,2,FALSE) -> 1.32 | BC11: =+VLOOKUP(BC$7*1000+FLOOR(BC6*4-3,1),hts_calculator!$A:$B,2,FALSE) -> 1.296
B12: Team B: | C12: =1-C11 -> 0.63879336 | D12: =+AC25^3.5/(AC25^3.5+Y27^3.5)*0.92 -> 0.27278199 | E12: =+AD25^3.5/(AD25^3.5+X27^3.5)*0.92 -> 0.34078442 | F12: =+AE25^3.5/(AE25^3.5+W27^3.5)*0.92 -> 0.28897557 | H12: MID | I12: H | J12: PDIM | K12: T | L12: Q | M12: Q | P12: =SUM(X7:X9) -> 6.958 | Q12: L/C/R | R12: =SUM(AD7:AD9) -> 1.6270358 | T12: 0.041 | U12: IFK | V12: =+VLOOKUP(J7*4-I8*4,lkup_simul!$A:$B,2,TRUE) -> 0.11607792 | W12: =(1-W13)*T12 -> 0.040754 | X12: =X$3*W12 -> 0.326032 | Y12: =X12*V12 -> 0.037845115 | Z12: =Z$4*T12 -> 0.0038707748 | AA12: =Z12*V12 -> 0.00044931147 | AB12: =+VLOOKUP(J8*4-I7*4,lkup_simul!$A:$B,2,TRUE) -> 0.046530572 | AC12: =(1-AC13)*T12 -> 0.040754 | AD12: =AD$3*AC12 -> 0.076238251 | AE12: =AD12*AB12 -> 0.0035474094 | AF12: =$AF$4*T12 -> 0.0096464195 | AG12: =AF12*AB12 -> 0.00044885342 | AI12: Offensive | AJ12: U score | AK12: 0.041 | AL12: =COUNTIF($I$11:$M$12,"U") -> 0 | AM12: =COUNTIF($I$17:$M$18,"U") -> 3 | AN12: =+IFERROR(IF(AL12=AM12,AW12,(AL12^$AW12)/(AL12^$AW12+AM12^$AW12)),0) -> 0 | AO12: =+AK12*VLOOKUP(MAX(AL12,AM12),lkup_simul!$DP:$DT,4,FALSE)*AN12*AO$3 -> 0 | AP12: =+AK12*VLOOKUP(MAX(AL12,AM12),lkup_simul!$DP:$DT,4,FALSE)*(1-AN12)*AO$3 -> 0.2375253 | AQ12: =HLOOKUP($K$8,conv_Kstars!$CB$6:$CY$27,$AY12,FALSE) -> 0.48 | AR12: =HLOOKUP($K$7,conv_Kstars!$CB$6:$CY$27,$AY12,FALSE) -> 0.45945946 | AS12: =+IFERROR(AO12*AQ12,0) -> 0 | AT12: =+IFERROR(AP12*AR12,0) -> 0.10913325 | AW12: =+IF($AO$2=4,IF(AL12=AM12,(AL12+1)/(AL12+1+AM12),IF(AL12>AM12,$AO$2,$AP$2)),IF($AO$2=2.5,IF(AL12=AM12,(AL12)/(AL12+1+AM12),IF(AL12>AM12,$AO$2,$AP$2)),IF($AO$2=3.5,IF(AL12=AM12,0.5,3.5)))) -> 4 | AX12: U | AY12: 14 | BA12: LS | BB12: =+IF(AA32=0,1,VLOOKUP(8000+AA32,hts_calculator!$J:$K,2,FALSE)) -> 1 | BC12: =+IF(AB32=0,1,VLOOKUP(8000+AB32,hts_calculator!$J:$K,2,FALSE)) -> 1 | BE12: =+IF($AA$36>0,hts_calculator!N3,IF($AA$35>0,hts_calculator!N4,hts_calculator!N2)) -> 0.3 | BF12: =+IF($AA$36>0,hts_calculator!N3,IF($AA$35>0,hts_calculator!O4,hts_calculator!O2)) -> 0.4 | BG12: =+IF($AB$36>0,hts_calculator!N3,IF($AB$35>0,hts_calculator!N4,hts_calculator!N2)) -> 0.3 | BH12: =+IF($AB$36>0,hts_calculator!N3,IF($AB$35>0,hts_calculator!O4,hts_calculator!O2)) -> 0.4
H13: DEF | I13: T | K13: Z | M13: Z | P13: =SUM(X10:X12) -> 0.994 | Q13: Set Piece | R13: =SUM(AD10:AD12) -> 0.23243369 | U13: LS | V13: =VLOOKUP(VALUE(AA32),lkup_simul!$N:$S,5,TRUE) -> 0.11 | W13: =IF(M7<>"Long Shots",0.6%,VLOOKUP(L7,lkup_simul!$BY:$CF,7,FALSE)+VLOOKUP(L7,lkup_simul!$BY:$CF,8,FALSE)) -> 0.006 | X13: =X$3*W13*(1-X4) -> 0.048 | Y13: =X13*V13 -> 0.00528 | AB13: =VLOOKUP(VALUE(AB32),lkup_simul!$N:$S,5,TRUE) -> 0.11 | AC13: =IF(VALUE(AB32)=0,0.6%,VLOOKUP(AB32,lkup_simul!$BY:$CF,7,FALSE)+VLOOKUP(AB32,lkup_simul!$BY:$CF,8,FALSE)) -> 0.006 | AD13: =AD$3*AC13*(1-AD4) -> 0.011224162 | AE13: =AD13*AB13 -> 0.0012346578 | AI13: Def / IM | AJ13: U mistake | AK13: 0.0235 | AL13: =COUNTIF($I$13:$M$13,"U")+COUNTIF($J$12:$L$12,"U") -> 0 | AM13: =COUNTIF($I$19:$M$19,"U")+COUNTIF($J$18:$L$18,"U") -> 5 | AN13: =1-IFERROR(IF(AL13=AM13,AW13,(AL13^$AW13)/(AL13^$AW13+AM13^$AW13)),0) -> 1 | AO13: =+AK13*VLOOKUP(MAX(AL13,AM13),lkup_simul!$DP:$DT,4,FALSE)*AN13*AO$3 -> 0.21823275 | AP13: =+AK13*VLOOKUP(MAX(AL13,AM13),lkup_simul!$DP:$DT,4,FALSE)*(1-AN13)*AO$3 -> 0 | AQ13: =HLOOKUP($K$8,conv_Kstars!$CB$6:$CY$27,$AY13,FALSE) -> 0.17251284 | AR13: =HLOOKUP($K$7,conv_Kstars!$CB$6:$CY$27,$AY13,FALSE) -> 0.16739618 | AS13: =+IFERROR(AO13*AQ13,0) -> 0.037647951 | AT13: =+IFERROR(AP13*AR13,0) -> 0 | AW13: =+IF($AO$2=4,IF(AL13=AM13,(AL13+1)/(AL13+1+AM13),IF(AL13>AM13,$AO$2,$AP$2)),IF($AO$2=2.5,IF(AL13=AM13,(AL13)/(AL13+1+AM13),IF(AL13>AM13,$AO$2,$AP$2)),IF($AO$2=3.5,IF(AL13=AM13,0.5,3.5)))) -> 4 | AX13: U | AY13: 12 | BA13: HTS | BB13: =100*BB9*BB10*BB11*BB12 -> 293.30403 | BC13: =100*BC9*BC10*BC11*BC12 -> 345.05154 | BE13: 0.3 | BF13: 0.4 | BG13: 0.3 | BH13: 0.4
C14: Att | D14: 11.75 | E14: 13.5 | F14: 15.5 | H14: K | K14: Z | P14: =X13 -> 0.048 | Q14: LS | R14: =AD13 -> 0.011224162 | U14: PNF | V14: 0.8 | Z14: =(SUM(X7:X12)-SUM(Y7:Y12))*AA19 -> 0.19761635 | AA14: =Z14*V14 -> 0.15809308 | AB14: 0.8 | AF14: =+(SUM(AD7:AD12)-SUM(AE7:AE12))*AB19 -> 0.11623789 | AG14: =AF14*AB14 -> 0.092990314 | AI14: WG / FW | AJ14: UOG | AK14: 0.0425 | AL14: =COUNTIF($I$12,"U")+COUNTIF($M$12,"U")+COUNTIF($I$11:$M$11,"U") -> 0 | AM14: =COUNTIF($I$18,"U")+COUNTIF($M$18,"U")+COUNTIF($I$17:$M$17,"U") -> 0 | AN14: =1-IFERROR(IF(AL14=AM14,AW14,(AL14^$AW14)/(AL14^$AW14+AM14^$AW14)),0) -> 1 | AO14: =+AK14*VLOOKUP(MAX(AL14,AM14),lkup_simul!$DP:$DT,4,FALSE)*AN14*AO$3 -> 0 | AP14: =+AK14*VLOOKUP(MAX(AL14,AM14),lkup_simul!$DP:$DT,4,FALSE)*(1-AN14)*AO$3 -> 0 | AQ14: =HLOOKUP($K$8,conv_Kstars!$CB$6:$CY$27,$AY14,FALSE) -> 0.19251888 | AR14: =HLOOKUP($K$7,conv_Kstars!$CB$6:$CY$27,$AY14,FALSE) -> 0.18680885 | AS14: =+IFERROR(AO14*AQ14,0) -> 0 | AT14: =+IFERROR(AP14*AR14,0) -> 0 | AW14: =+IF($AO$2=4,IF(AL14=AM14,(AL14+1)/(AL14+1+AM14),IF(AL14>AM14,$AO$2,$AP$2)),IF($AO$2=2.5,IF(AL14=AM14,(AL14)/(AL14+1+AM14),IF(AL14>AM14,$AO$2,$AP$2)),IF($AO$2=3.5,IF(AL14=AM14,0.5,3.5)))) -> 0 | AX14: U | AY14: 13
B15: Team A | C15: Mid | E15: 11.5 | P15: =SUM(Z7:Z13) -> 0.094409141 | Q15: CA | R15: =SUM(AF7:AF13) -> 0.23527852 | U15: Total | V15: =Y15/X15 -> 0.19590625 | W15: =SUM(W7:W13) -> 1 | X15: =SUM(X7:X13) -> 8 | Y15: =SUM(Y7:Y13) -> 1.56725 | Z15: =SUM(Z7:Z14) -> 0.29202549 | AA15: =SUM(AA7:AA14) -> 0.17663738 | AB15: =AE15/AD15 -> 0.024245785 | AC15: =SUM(AC7:AC13) -> 1 | AD15: =SUM(AD7:AD13) -> 1.8706937 | AE15: =SUM(AE7:AE13) -> 0.045356436 | AF15: =SUM(AF7:AF14) -> 0.35151642 | AG15: =SUM(AG7:AG13) -> 0.0055827249 | AI15: Poss | AJ15: C-A | AK15: 0.1 | AN15: =IF(D4="Ratings",X26/(X26+AD26),VLOOKUP(ROUND(C7,2),lkup_simul!$GP:$GQ,2,FALSE)) -> 0.61351179 | AO15: =+AK15*AN15*AO$3 -> 0.12576992 | AP15: =+AK15*(1-AN15)*AO$3 -> 0.079230083 | AQ15: =VLOOKUP((J7-I8)*4,lkup_simul!$EE:$EF,2,TRUE)*VLOOKUP(K8-AA32/4,lkup_simul!$EB:$EC,2,TRUE) -> 0.4094 | AR15: =VLOOKUP((J8-I7)*4,lkup_simul!$EE:$EF,2,TRUE)*VLOOKUP(K7-AB32/4,lkup_simul!$EB:$EC,2,TRUE) -> 0.3628625 | AS15: =+IFERROR(AO15*AQ15,0) -> 0.051490204 | AT15: =+IFERROR(AP15*AR15,0) -> 0.028749626 | AX15: O
C16: Def | D16: 13.25 | E16: 16.75 | F16: 16.75 | K16: Team B | P16: =Z14 -> 0.19761635 | Q16: PNF | R16: =AF14 -> 0.11623789 | Z16: Missed Normal: | AA16: =X15-Y15 -> 6.43275 | AB16: =AD15-AE15 -> 1.8253373 | AI16: Wingers | AJ16: W-A | AK16: 0.08 | AL16: =COUNTA($I12,$M12) -> 2 | AM16: =COUNTA($I18,$M18) -> 2 | AN16: =+IFERROR(IF(AL16=AM16,AW16,(AL16^$AW16)/(AL16^$AW16+AM16^$AW16)),0) -> 0.4 | AO16: =+AK16*VLOOKUP(MAX(AL16,AM16),lkup_simul!$DP:$DT,4,FALSE)*AN16*AO$3 -> 0.1268704 | AP16: =+AK16*VLOOKUP(MAX(AL16,AM16),lkup_simul!$DP:$DT,4,FALSE)*(1-AN16)*AO$3 -> 0.1903056 | AQ16: =HLOOKUP($K$8,conv_Kstars!$CB$6:$CY$27,$AY16,FALSE) -> 0.33 | AR16: =HLOOKUP($K$7,conv_Kstars!$CB$6:$CY$27,$AY16,FALSE) -> 0.32 | AS16: =+IFERROR(AO16*AQ16,0) -> 0.041867232 | AT16: =+IFERROR(AP16*AR16,0) -> 0.060897792 | AW16: =+IF($AO$2=4,IF(AL16=AM16,(AL16+1)/(AL16+1+AM16),IF(AL16>AM16,$AO$2,$AP$2)),IF($AO$2=2.5,IF(AL16=AM16,(AL16)/(AL16+1+AM16),IF(AL16>AM16,$AO$2,$AP$2)),IF($AO$2=3.5,IF(AL16=AM16,0.5,3.5)))) -> 0.4 | AX16: O | AY16: 16
H17: FW | J17: PNF | L17: Q | P17: =IF(J4="Yes",AO19,0.5*AO3) -> 1.0988378 | Q17: SE | R17: =IF(J4="Yes",AP19,0.5*AO3) -> 1.7177461 | Z17: PDIM: | AA17: =COUNTIF(J12:L12,"PDIM") -> 1 | AB17: =COUNTIF(J18:L18,"PDIM") -> 0 | AI17: Offensive | AJ17: T | AK17: 0.0954 | AL17: =COUNTIF($I$11:$M$12,"T")*MIN(1,COUNTIF(I18:M20,"H")+COUNTIF(I18:M20,"H+SP")) -> 0 | AM17: =COUNTIF($I$17:$M$18,"T")*MIN(1,COUNTIF(I12:M14,"H")+COUNTIF(I12:M14,"H+SP")) -> 0 | AN17: =+IFERROR(IF(AL17=AM17,AW17,(AL17^$AW17)/(AL17^$AW17+AM17^$AW17)),0) -> 0 | AO17: =+AK17*VLOOKUP(MAX(AL17,AM17),lkup_simul!$DP:$DT,4,FALSE)*AN17*AO$3 -> 0 | AP17: =+AK17*VLOOKUP(MAX(AL17,AM17),lkup_simul!$DP:$DT,4,FALSE)*(1-AN17)*AO$3 -> 0 | AQ17: =HLOOKUP($K$8,conv_Kstars!$CB$6:$CY$27,$AY17,FALSE) -> 0.24486983 | AR17: =HLOOKUP($K$7,conv_Kstars!$CB$6:$CY$27,$AY17,FALSE) -> 0.23986983 | AS17: =+IFERROR(AO17*AQ17,0) -> 0 | AT17: =+IFERROR(AP17*AR17,0) -> 0 | AW17: =+IF($AO$2=4,IF(AL17=AM17,(AL17+1)/(AL17+1+AM17),IF(AL17>AM17,$AO$2,$AP$2)),IF($AO$2=2.5,IF(AL17=AM17,(AL17)/(AL17+1+AM17),IF(AL17>AM17,$AO$2,$AP$2)),IF($AO$2=3.5,IF(AL17=AM17,0.5,3.5)))) -> 0 | AX17: T | AY17: 9
C18: Att | D18: 13.25 | E18: 14.5 | F18: 10.75 | H18: MID | I18: Q | J18: U | K18: U | L18: U | M18: Q | P18: =SUM(P19:P24) -> 2.0913468 | Q18: Goals | R18: =SUM(R19:R24) -> 0.71968398 | Z18: PNF_CD Opp: | AA18: =COUNTIF(J11:L11,"PNF")&"_"&COUNTA(J19:L19) -> 1_2 | AB18: =COUNTIF(J17:L17,"PNF")&"_"&COUNTA(J13:L13) -> 1_1 | AI18: n/a | AJ18: All Others | AK18: 0.092 | AN18: 0.5 | AO18: =+AK18*AN18*AO$3 -> 0.0943 | AP18: =+AK18*(1-AN18)*AO$3 -> 0.0943 | AQ18: =HLOOKUP($K$8,conv_Kstars!$CB$6:$CY$27,$AY18,FALSE) -> 0.18929049 | AR18: =HLOOKUP($K$7,conv_Kstars!$CB$6:$CY$27,$AY18,FALSE) -> 0.17204775 | AS18: =+IFERROR(AO18*AQ18,0) -> 0.017850093 | AT18: =+IFERROR(AP18*AR18,0) -> 0.016224102 | AX18: O | AY18: 18
B19: Team B | C19: Mid | E19: 13.75 | H19: DEF | I19: U | K19: U | L19: Q | P19: =SUM(Y7:Y9) -> 1.3916 | Q19: L/C/R | R19: =SUM(AE7:AE9) -> 0.016270358 | Z19: PNF event conv%: | AA19: =+VLOOKUP(AA18,lkup_simul!$W:$X,2,FALSE) -> 0.030925732 | AB19: =+VLOOKUP(AB18,lkup_simul!$W:$X,2,FALSE) -> 0.064030648 | AI19: Total | AJ19: Total | AO19: =SUM(AO5:AO18) -> 1.0988378 | AP19: =SUM(AP5:AP18) -> 1.7177461 | AQ19: =AS19/AO19 -> 0.3162063 | AR19: =AT19/AP19 -> 0.33518021 | AS19: =SUM(AS5:AS18) -> 0.34745945 | AT19: =SUM(AT5:AT18) -> 0.57575451
C20: Def | D20: 14 | E20: 18 | F20: 12.5 | H20: K | K20: Z | P20: =SUM(Y10:Y12) -> 0.17036997 | Q20: Set Piece | R20: =SUM(AE10:AE12) -> 0.02785142 | Z20: AIM% shift: | AA20: =IF(VALUE(AA36)=0,0,VLOOKUP(AA36,lkup_simul!$CH:$CO,8,TRUE)) -> 0 | AB20: =IF(VALUE(AB36)=0,0,VLOOKUP(AB36,lkup_simul!$CH:$CO,8,TRUE)) -> 0 | AI20: Tech D | AJ20: Tech D | AL20: =COUNTIF($I$13:$M$13,"T") -> 1 | AM20: =COUNTIF($I$19:$M$20,"T") -> 0
P21: =Y13 -> 0.00528 | Q21: LS | R21: =AE13 -> 0.0012346578 | Z21: AOW% shift: | AA21: =IF(VALUE(AA35)=0,0,VLOOKUP(AA35,lkup_simul!$CQ:$CX,8,TRUE)) -> 0 | AB21: =IF(VALUE(AB35)=0,0,VLOOKUP(AB35,lkup_simul!$CQ:$CX,8,TRUE)) -> 0
H22: Spec | I22: Definition | K22: Spec | L22: Definition | P22: =SUM(AA7:AA13) -> 0.018544296 | Q22: CA | R22: =SUM(AG7:AG13) -> 0.0055827249 | Z22: PK/(PK+DFK): | AA22: =VLOOKUP(J$7,dfk_pk!$A$8:$AS$19,HLOOKUP(I$8,dfk_pk!$D$4:$O$5,2,TRUE)+30,TRUE) -> 0.28 | AB22: =VLOOKUP(J$8,dfk_pk!$A$8:$AS$19,HLOOKUP(I$7,dfk_pk!$D$4:$O$5,2,TRUE)+30,TRUE) -> 0.27 | AM22: Spec | AN22: Spec | AO22: SE A | AP22: SE B | AQ22: Conv% A | AR22: Conv% B | AS22: SE xG A | AT22: SE xG B
D23: HTS: | E23: =P9 -> 293.30403 | F23: =R9 -> 345.05154 | I23: no player | K23: H+SP | L23: Head + Set Piece Taker | P23: =AA14 -> 0.15809308 | Q23: PNF | R23: =AG14 -> 0.092990314 | AM23: Quick | AN23: Q | AO23: =+SUMIFS(AO$5:AO$18,$AX$5:$AX$18,$AN23) -> 0.41860731 | AP23: =+SUMIFS(AP$5:AP$18,$AX$5:$AX$18,$AN23) -> 0.55814307 | AQ23: =+IFERROR(AS23/AO23,"") -> 0.32404951 | AR23: =+IFERROR(AT23/AP23,"") -> 0.3160116 | AS23: =+SUMIFS(AS$5:AS$18,$AX$5:$AX$18,$AN23) -> 0.13564949 | AT23: =+SUMIFS(AT$5:AT$18,$AX$5:$AX$18,$AN23) -> 0.17637968
D24: Home/Away: | E24: Neutral | F24: Neutral | H24: Q | I24: Quick | K24: PNF | L24: Powerful Normal Forward | P24: =IF(J4="Yes",AS19,0.48*P17) -> 0.34745945 | Q24: SE | R24: =IF(J4="Yes",AT19,0.48*R17) -> 0.57575451 | AA24: Hat Ratings | AM24: Head | AN24: H | AO24: =+SUMIFS(AO$5:AO$18,$AX$5:$AX$18,$AN24) -> 0.11505746 | AP24: =+SUMIFS(AP$5:AP$18,$AX$5:$AX$18,$AN24) -> 0 | AQ24: =+IFERROR(AS24/AO24,"") -> 0.54715684 | AR24: =+IFERROR(AT24/AP24,"") | AS24: =+SUMIFS(AS$5:AS$18,$AX$5:$AX$18,$AN24) -> 0.062954475 | AT24: =+SUMIFS(AT$5:AT$18,$AX$5:$AX$18,$AN24) -> 0
D25: Extra time: | E25: Y | H25: U | I25: Unpredictable | K25: PDIM | L25: Powerful Defensive Inner Midfield | W25: =+(D14*4-3) -> 44 | X25: =+(E14*4-3) -> 51 | Y25: =+(F14*4-3) -> 59 | AA25: Att | AC25: =+(D18*4-3) -> 50 | AD25: =+(E18*4-3) -> 55 | AE25: =+(F18*4-3) -> 40 | AM25: Unpred | AN25: U | AO25: =+SUMIFS(AO$5:AO$18,$AX$5:$AX$18,$AN25) -> 0.21823275 | AP25: =+SUMIFS(AP$5:AP$18,$AX$5:$AX$18,$AN25) -> 0.79576736 | AQ25: =+IFERROR(AS25/AO25,"") -> 0.17251284 | AR25: =+IFERROR(AT25/AP25,"") -> 0.36883054 | AS25: =+SUMIFS(AS$5:AS$18,$AX$5:$AX$18,$AN25) -> 0.037647951 | AT25: =+SUMIFS(AT$5:AT$18,$AX$5:$AX$18,$AN25) -> 0.2935033
D26: Manmarking (enter # of teams playing MM): | E26: 1 | H26: H | I26: Head | P26: =P18 -> 2.0913468 | Q26: xG | R26: =R18 -> 0.71968398 | S26: Win A | T26: Draw | U26: Win B | X26: =+(E15*4-3) -> 43 | AA26: Mid | AD26: =+(E19*4-3) -> 52 | AM26: Tech | AN26: T | AO26: =+SUMIFS(AO$5:AO$18,$AX$5:$AX$18,$AN26) -> 0 | AP26: =+SUMIFS(AP$5:AP$18,$AX$5:$AX$18,$AN26) -> 0 | AQ26: =+IFERROR(AS26/AO26,"") | AR26: =+IFERROR(AT26/AP26,"") | AS26: =+SUMIFS(AS$5:AS$18,$AX$5:$AX$18,$AN26) -> 0 | AT26: =+SUMIFS(AT$5:AT$18,$AX$5:$AX$18,$AN26) -> 0
D27: HTSN: | E27: =E23*VLOOKUP(E24,hts_calculator!$M$14:$N$18,2,FALSE)*VLOOKUP($E25,hts_calculator!$M$20:$N$21,2,FALSE)*VLOOKUP($E26,hts_calculator!$M$9:$N$11,2,FALSE) -> 371.0296 | F27: =F23*VLOOKUP(F24,hts_calculator!$M$14:$N$18,2,FALSE)*VLOOKUP($E25,hts_calculator!$M$20:$N$21,2,FALSE)*VLOOKUP($E26,hts_calculator!$M$9:$N$11,2,FALSE) -> 436.49019 | H27: T | I27: Technical | P27: =+POISSON(Q27,P$26,FALSE) -> 0.12352067 | Q27: 0 | R27: =+POISSON(Q27,R$26,FALSE) -> 0.4869061 | S27: 0 | T27: =+R27*P27 -> 0.060142967 | U27: =+P27-S27-T27 -> 0.0633777 | W27: =+(D16*4-3) -> 50 | X27: =+(E16*4-3) -> 64 | Y27: =+(F16*4-3) -> 64 | AA27: Def | AC27: =+(D20*4-3) -> 53 | AD27: =+(E20*4-3) -> 69 | AE27: =+(F20*4-3) -> 47 | AM27: Other | AN27: O | AO27: =+SUMIFS(AO$5:AO$18,$AX$5:$AX$18,$AN27) -> 0.34694032 | AP27: =+SUMIFS(AP$5:AP$18,$AX$5:$AX$18,$AN27) -> 0.36383568 | AQ27: =+IFERROR(AS27/AO27,"") -> 0.32053792 | AR27: =+IFERROR(AT27/AP27,"") -> 0.29098718 | AS27: =+SUMIFS(AS$5:AS$18,$AX$5:$AX$18,$AN27) -> 0.11120753 | AT27: =+SUMIFS(AT$5:AT$18,$AX$5:$AX$18,$AN27) -> 0.10587152
F28: HTSN is HTS Neutral (adjusted for location, extra time, manmark) | H28: Z | I28: no specialty, or other (Support / Regainer) | P28: =+POISSON(Q28,P$26,FALSE) -> 0.25832455 | Q28: 1 | R28: =+POISSON(Q28,R$26,FALSE) -> 0.35041852 | S28: =+SUM(R$27:R27)*P28 -> 0.1257798 | T28: =+R28*P28 -> 0.090521708 | U28: =+P28-S28-T28 -> 0.042023043 | AM28: All | AN28: All | AO28: =SUM(AO23:AO27) -> 1.0988378 | AP28: =SUM(AP23:AP27) -> 1.7177461 | AQ28: =+IFERROR(AS28/AO28,"") -> 0.3162063 | AR28: =+IFERROR(AT28/AP28,"") -> 0.33518021 | AS28: =SUM(AS23:AS27) -> 0.34745945 | AT28: =SUM(AT23:AT27) -> 0.57575451
P29: =+POISSON(Q29,P$26,FALSE) -> 0.27012311 | Q29: 2 | R29: =+POISSON(Q29,R$26,FALSE) -> 0.1260953 | S29: =+SUM(R$27:R28)*P29 -> 0.22618073 | T29: =+R29*P29 -> 0.034061254 | U29: =+P29-S29-T29 -> 0.0098811237
H30: Notes: | P30: =+POISSON(Q30,P$26,FALSE) -> 0.18830703 | Q30: 3 | R30: =+POISSON(Q30,R$26,FALSE) -> 0.030249589 | S30: =+SUM(R$27:R29)*P30 -> 0.18141875 | T30: =+R30*P30 -> 0.0056962103 | U30: =+P30-S30-T30 -> 0.0011920751 | Z30: Tactic | AA30: Level A | AB30: Level B | AO30: Q stop adjustment factor; 0% means that all Q events get stopped
H31: For a projection, CA rating should be reduced by -0.5 rating points | P31: =+POISSON(Q31,P$26,FALSE) -> 0.098453828 | Q31: 4 | R31: =+POISSON(Q31,R$26,FALSE) -> 0.0054425361 | S31: =+SUM(R$27:R30)*P31 -> 0.097830567 | T31: =+R31*P31 -> 0.00053583851 | U31: =+P31-S31-T31 -> 8.7422106e-05 | Z31: Counter Attacks | AA31: =IF($M$7=Z31,$L$7,0) -> 0 | AB31: =IF($M$8=Z31,$L$8,0) -> 0
H32: for each opposing Q defenders that "cancels out" a Q attacker | P32: =+POISSON(Q32,P$26,FALSE) -> 0.041180219 | Q32: 5 | R32: =+POISSON(Q32,R$26,FALSE) -> 0.00078338121 | S32: =+SUM(R$27:R31)*P32 -> 0.041143653 | T32: =+R32*P32 -> 3.225981e-05 | U32: =+P32-S32-T32 -> 4.3061779e-06 | Z32: Long Shots | AA32: =IF($M$7=Z32,$L$7,0) -> 0 | AB32: =IF($M$8=Z32,$L$8,0) -> 0 | AO32: =B15 -> Team A | AQ32: =IF(J11="Q",IF(M19="Q",0,1+IF(L19="Q",-0.25,0)),"") | AR32: =IF(K11="Q",IF(K19="Q",0,1+IF(L19="Q",-0.25,0)+IF(J19="Q",-0.25,0)),"") | AS32: =IF(L11="Q",IF(I19="Q",0,1+IF(J19="Q",-0.25,0)),"") -> 1
H33: For an already played match, do not adjust (HT does this already in match report). | P33: =+POISSON(Q33,P$26,FALSE) -> 0.014353687 | Q33: 6 | R33: =+POISSON(Q33,R$26,FALSE) -> 9.3964485e-05 | S33: =+SUM(R$27:R32)*P33 -> 0.014352186 | T33: =+R33*P33 -> 1.3487368e-06 | U33: =+P33-S33-T33 -> 1.5221512e-07 | Z33: Play Creatively | AA33: =IF($M$7=Z33,$L$7,0) -> 0 | AB33: =IF($M$8=Z33,$L$8,0) -> 26 | AH33: =IF(AA33*AB33>0,FLOOR(AVERAGE(AA33:AB33),1),MAX(AA33:AB33)) -> 26 | AI33: =MIN(AA33*AB33,0.4)+1 -> 1 | AO33: =SUM(AP32:AT33)/AL5 -> 1 | AP33: =IF(I12="Q",IF(M19="Q",0,1+IF(L19="Q",-0.25,0)),"") | AQ33: =IF(J12="Q",IF(L19="Q",0,1+IF(K19="Q",-0.25,0)+IF(M19="Q",-0.25,0)),"") | AR33: =IF(K12="Q",IF(K19="Q",0,1+IF(L19="Q",-0.25,0)+IF(J19="Q",-0.25,0)),"") | AS33: =IF(L12="Q",IF(J19="Q",0,1+IF(I19="Q",-0.25,0)+IF(K19="Q",-0.25,0)),"") -> 1 | AT33: =IF(M12="Q",IF(I19="Q",0,1+IF(J19="Q",-0.25,0)),"") -> 1
P34: =+POISSON(Q34,P$26,FALSE) -> 0.0042883623 | Q34: 7 | R34: =+POISSON(Q34,R$26,FALSE) -> 9.6606764e-06 | S34: =+SUM(R$27:R33)*P34 -> 0.0042883169 | T34: =+R34*P34 -> 4.1428481e-08 | U34: =+P34-S34-T34 -> 4.0478906e-09 | Z34: Pressing | AA34: =IF($M$7=Z34,$L$7,0) -> 0 | AB34: =IF($M$8=Z34,$L$8,0) -> 0
D35: 27 | P35: =+POISSON(Q35,P$26,FALSE) -> 0.0011210566 | Q35: 8 | R35: =+POISSON(Q35,R$26,FALSE) -> 8.6907925e-07 | S35: =+SUM(R$27:R34)*P35 -> 0.0011210555 | T35: =+R35*P35 -> 9.7428703e-10 | U35: =+P35-S35-T35 -> 8.3905845e-11 | Z35: Attack on Wings | AA35: =IF($M$7=Z35,$L$7,0) -> 0 | AB35: =IF($M$8=Z35,$L$8,0) -> 0 | AO35: =B19 -> Team B | AQ35: =IF(J17="Q",IF(M13="Q",0,1+IF(L13="Q",-0.25,0)),"") | AR35: =IF(K17="Q",IF(K13="Q",0,1+IF(L13="Q",-0.25,0)+IF(J13="Q",-0.25,0)),"") | AS35: =IF(L17="Q",IF(I13="Q",0,1+IF(J13="Q",-0.25,0)),"") -> 1
P36: =+POISSON(Q36,P$26,FALSE) -> 0.00026050201 | Q36: 9 | R36: =+POISSON(Q36,R$26,FALSE) -> 6.9495824e-08 | S36: =+SUM(R$27:R35)*P36 -> 0.00026050199 | T36: =+R36*P36 -> 1.8103802e-11 | U36: =+P36-S36-T36 -> 1.3935557e-12 | Z36: Attack in Middle | AA36: =IF($M$7=Z36,$L$7,0) -> 0 | AB36: =IF($M$8=Z36,$L$8,0) -> 0 | AO36: =SUM(AP35:AT36)/AM5 -> 1 | AP36: =IF(I18="Q",IF(M13="Q",0,1+IF(L13="Q",-0.25,0)),"") -> 1 | AQ36: =IF(J18="Q",IF(L13="Q",0,1+IF(K13="Q",-0.25,0)+IF(M13="Q",-0.25,0)),"") | AR36: =IF(K18="Q",IF(K13="Q",0,1+IF(L13="Q",-0.25,0)+IF(J13="Q",-0.25,0)),"") | AS36: =IF(L18="Q",IF(J13="Q",0,1+IF(I13="Q",-0.25,0)+IF(K13="Q",-0.25,0)),"") | AT36: =IF(M18="Q",IF(I13="Q",0,1+IF(J13="Q",-0.25,0)),"") -> 1
P37: =1-POISSON(Q36,P$26,TRUE) -> 6.6983765e-05 | Q37: 10 | R37: =1-POISSON(Q36,R$26,TRUE) -> 5.3495006e-09 | S37: =+SUM(R$27:R36)*P37 -> 6.6983765e-05 | T37: =+R37*P37 -> 3.5832969e-13 | U37: =+P37-S37-T37 -> 5.8349155e-21
Q38: League | S38: =+SUM(S27:S37) -> 0.69244254 | T38: =+SUM(T27:T37) -> 0.19099163 | U38: =+SUM(U27:U37) -> 0.11656583

Sheet lkup_simul
A1: Updated Nov 2023 | N1: LS | O1: match | P1: event | Q1: goal | S1: Conv% | AZ1: assumes 3 missed chances per match | BA1: actual freq per match | BB1: TacticSkill | BC1: E_CA | BD1: Opp_E_NormalMissed | BE1: % CA | BF1: Selected | BH1: CA lkup | BI1: CA %conv | DA1: CORNER HEAD | DE1: CORNER HEAD | EX1: (no tactic) | FZ1: Percent | GA1: Yes | GD1: 2 | GE1: 3 | GF1: 4 | GG1: 5 | GI1: # Tech D | GJ1: MNC | GK1: T CA | GL1: CA% | GM1: Select | GP1: actual poss | GQ1: linear poss | GR1: y/x | GS1: x=10 | GT1: y | GU1: linear | GV1: actual | GX1: chance of draw in the cup | HD1: determine odds to win PKs
N2: 0 | R2: 0.11 | AA2: 0 | AC2: Tac Skill | AD2: Select | AH2: 1 | AI2: =+AH2 -> 1 | BA2: 0.042 | BB2: 2D | BF2: =+BA2/3 -> 0.014 | BH2: 2D | BI2: 0.018111516 | DP2: se players | DQ2: factor | DR2: C-H factor | DU2: =DU3&DU4&DU5&DU6&DU7&DU8&DU9&DU10&DU11&DU12&DU13 -> 0:0,1:1,2:1.934,3:2.826,4:3.7,5:4.53,6:5.328,7:6.09,8:6.816,9:7.506,10:8.16, | DY2: ISP Gap | DZ2: Conv% | EB2: K Stars | EC2: K Factor | EX2: Counter Attacks | FP2: LS | FQ2: % pressed | FS2: Pressing | FT2: adj | FW2: Z | FX2: Z | FZ2: Ratings | GA2: No | GC2: Total | GD2: 0.018111516 | GE2: 0.036575107 | GF2: 0.060231577 | GG2: 0.074636837 | GI2: 1 | GJ2: 774240 | GK2: 5193 | GL2: 0.0067072226 | GM2: =+GL2 -> 0.0067072226 | GP2: 0 | GQ2: 0 | GR2: =(1/GP2-1)^(1/3) -> #DIV/0! | GS2: 10 | GT2: =+GS2*(1-GQ2)/GQ2 -> #DIV/0! | GU2: =+GS2/(GT2+GS2) -> #DIV/0! | GV2: =+GS2^3/(GS2^3+GT2^3) -> #DIV/0! | GX2: multiply the two factors together | HD2: after 120'
N3: 1 | O3: 2788 | P3: 5737 | Q3: 182 | R3: =S3 -> 0.038732394 | S3: 0.038732394 | AA3: 1 | AC3: No PC | AD3: 1 | AH3: =AH4-0.08 -> 1.1 | AI3: =+AH3 -> 1.1 | BA3: 0.097 | BB3: 3D | BF3: =+BA3/3 -> 0.032333333 | BH3: 3D | BI3: 0.036575107 | BY3: long shots | DP3: 0 | DQ3: 0 | DR3: 0 | DS3: 0 | DT3: 0 | DU3: =DP3&":"&DS3&"," -> 0:0, | DV3: -99 | DX3: -38.5 | DY3: -99 | DZ3: 0.22 | EB3: 0 | EC3: 1.37 | EM3: Conv non-LS | EN3: 7 | EO3: 8 | EP3: 9 | EQ3: 10 | EX3: Long Shots | FA3: CA count | FB3: 2 | FC3: 3 | FD3: 4 | FE3: 5 | FF3: Total | FH3: Press Tactic Skill | FI3: Match | FJ3: Press% | FK3: Freq LS Press | FL3: Freq Long Shot | FM3: Avg Points LS Team | FN3: Avg LS Tactic Skill | FP3: 0 | FQ3: 0 | FS3: 0 | FT3: 0 | FW3: Q | FX3: Q | GC3: 1 | GD3: 0.01147977 | GE3: 0.019126739 | GF3: 0.041626331 | GG3: 0.045116773 | GI3: 2 | GJ3: 122896 | GK3: 1087 | GL3: 0.008844877 | GM3: =+GL3 -> 0.008844877 | GN3: =+GM3/GM$2 -> 1.3187093 | GP3: =+ROUND(GP2+1%,2) -> 0.01 | GQ3: =1/(1+GR3) -> 0.17774412 | GR3: =(1/GP3-1)^(1/3) -> 4.626065 | GS3: 10 | GT3: =+GS3*(1-GQ3)/GQ3 -> 46.26065 | GU3: =+GS3/(GT3+GS3) -> 0.17774412 | GV3: =+GS3^3/(GS3^3+GT3^3) -> 0.01 | GX3: first factor is the average xG of the teams | HD3: based on gap in ISP Attack rating
N4: 3 | O4: 3118 | P4: 5267 | Q4: 273 | R4: =S4 -> 0.050018389 | S4: 0.050018389 | W4: 0_0 | X4: 0 | Y4: 0 | AA4: =+AA3+1 -> 2 | AC4: <7 | AH4: =AH5-0.08 -> 1.18 | AI4: =+AH4 -> 1.18 | AJ4: Freq | AK4: Player A | AL4: Player B | AM4: % Event A | AN4: Freq A | AO4: Freq B | BA4: 0.203 | BB4: 4D | BF4: =+BA4/3 -> 0.067666667 | BH4: 4D | BI4: 0.060231577 | BY4: TacticSkill | BZ4: Normal | CA4: LS | CB4: LS N-T | CC4: % LS | CD4: % LS N-T | CE4: select | CI4: AIM Rating | CJ4: E_Att_Mid | CK4: E_Att_Wing | CL4: E_AIM_AOW | CM4: % Mid | CN4: % Convert | CO4: select | CR4: AOW Rating | CS4: E_Att_Mid | CT4: E_Att_Wing | CU4: E_AIM_AOW | CV4: % Wing | CW4: % Convert | CX4: select | DA4: Head gap | DB4: Conv% | DE4: ISP gap | DF4: ISP factor | DH4: ISP gap | DI4: ISP Factor | DJ4: calc steps | DK4: calc steps | DL4: calc steps | DM4: calc steps | DN4: calc steps | DP4: 1 | DQ4: 1 | DR4: =DT4/DP4 -> 1 | DS4: =$DP4*DQ4 -> 1 | DT4: 1 | DU4: =DP4&":"&DS4&"," -> 1:1, | DV4: -40 | DX4: =DY4+1.5 -> -34.5 | DY4: -36 | DZ4: 0.25 | EB4: 3.5 | EC4: 1.33 | EE4: ISP gap | EF4: ISP Factor | EG4: calc steps | EH4: calc steps | EI4: calc steps | EJ4: calc steps | EK4: calc steps | EM4: -4 | EQ4: 0.47 | ES4: =EN14/EN4-1 -> #DIV/0! | ET4: =EO14/EO4-1 -> #DIV/0! | EU4: =EP14/EP4-1 -> #DIV/0! | EV4: =EQ14/EQ4-1 -> 0.36170213 | EX4: Play Creatively | FA4: 0 | FB4: 0.96 | FC4: 0.91 | FD4: 0.81 | FE4: 0.74 | FF4: 0.87 | FH4: New | FI4: 888 | FJ4: 0.52 | FK4: 0.9 | FL4: 0.85 | FM4: 1.97 | FN4: 18.8 | FP4: 1 | FQ4: =FQ5+0.5% -> 0.565 | FS4: 1 | FT4: 0.9 | FW4: H | FX4: H | GC4: 5 | GD4: 0.009483667 | GE4: 0.021601988 | GF4: 0.03784693 | GG4: 0.062234795 | GI4: 3 | GJ4: 14499 | GK4: 159 | GL4: 0.010966274 | GM4: =+GM2*1.6 -> 0.010731556 | GN4: =+GM4/GM$2 -> 1.6 | GP4: =+ROUND(GP3+1%,2) -> 0.02 | GQ4: =1/(1+GR4) -> 0.21462425 | GR4: =(1/GP4-1)^(1/3) -> 3.6593057 | GS4: 10 | GT4: =+GS4*(1-GQ4)/GQ4 -> 36.593057 | GU4: =+GS4/(GT4+GS4) -> 0.21462425 | GV4: =+GS4^3/(GS4^3+GT4^3) -> 0.02 | GX4: second factor is the gap in xG | HD4: which correlates with set pieces
N5: 4 | O5: 4039 | P5: 5620 | Q5: 437 | R5: =S5 -> 0.06527977 | S5: 0.06527977 | W5: 0_1 | X5: 0 | Y5: 0 | AA5: =+AA4+1 -> 3 | AC5: 7 | AD5: 1.58 | AH5: =AH6-0.08 -> 1.26 | AI5: =+AH5 -> 1.26 | BA5: 0.292 | BB5: 5D | BF5: =+BA5/3 -> 0.097333333 | BH5: 5D | BI5: 0.074636837 | BM5: EventName | BN5: E | BO5: CA | BP5: Normal | BQ5: Normal (remove PK & LS) | BS5: EventName | BT5: E | BU5: % | BV5: % no LS_NT | BY5: 2 | BZ5: 20 | CA5: 1 | CB5: 0 | CC5: =CA5/(BZ5+CA5) -> 0.047619048 | CD5: 0 | CE5: =CE6-1.5% -> 0.035 | CF5: =CF6-0.025% -> 0.00425 | CH5: 1 | CI5: <17 | CJ5: 631 | CK5: 441 | CL5: 189 | CM5: 0.59 | CN5: =CL5/(CK5+CL5) -> 0.3 | CO5: 0.3 | CQ5: 1 | CR5: <14 | CS5: 229 | CT5: 618 | CU5: 147 | CV5: 0.73 | CW5: 0.39 | CX5: 0.39 | DA5: -11 | DB5: 0 | DD5: =-46-0.5 -> -46.5 | DE5: <-44 | DF5: 0.406 | DH5: -99 | DI5: 0.4 | DP5: 2 | DQ5: 0.967 | DR5: =DT5/DP5 -> 1.125 | DS5: =$DP5*DQ5 -> 1.934 | DT5: 2.25 | DU5: =DP5&":"&DS5&"," -> 2:1.934, | DV5: 0.39 | DX5: =DY5+1.5 -> -30.5 | DY5: -32 | DZ5: 0.28 | EB5: 4 | EC5: 1.29 | EE5: -99 | EF5: =EF6-(EF7-EF6) -> 0.20125 | EM5: 0 | EO5: 0.55 | EP5: 0.54 | EQ5: 0.46 | ES5: =EN15/EN5-1 -> #DIV/0! | ET5: =EO15/EO5-1 -> 0.25454545 | EU5: =EP15/EP5-1 -> 0.22222222 | EV5: =EQ15/EQ5-1 -> 0.63043478 | EX5: Pressing | FA5: 1 | FB5: 0.04 | FC5: 0.09 | FD5: 0.17 | FE5: 0.23 | FF5: 0.12 | FH5: <6 | FI5: 113 | FJ5: 0.48 | FK5: 0.96 | FL5: 1.05 | FM5: 2.26 | FN5: 17.5 | FP5: 8 | FQ5: 0.56 | FS5: 5 | FT5: =FT4+0.025 -> 0.925 | FW5: H+SP | FX5: H+SP | GC5: 5.5 | GD5: 0.011168663 | GE5: 0.027821317 | GF5: 0.048299845 | GG5: 0.059481903 | GI5: 4 | GJ5: 1150 | GK5: 15 | GL5: 0.013043478 | GM5: =+GM2*1.8 -> 0.012073001 | GN5: =+GM5/GM$2 -> 1.8 | GP5: =+ROUND(GP4+1%,2) -> 0.03 | GQ5: =1/(1+GR5) -> 0.23890366 | GR5: =(1/GP5-1)^(1/3) -> 3.1857877 | GS5: 10 | GT5: =+GS5*(1-GQ5)/GQ5 -> 31.857877 | GU5: =+GS5/(GT5+GS5) -> 0.23890366 | GV5: =+GS5^3/(GS5^3+GT5^3) -> 0.03 | HD5: ISP Att Gap | HE5: Win% PK
A6: isp | G6: Pressing | H6: opp normal | I6: opp LS | N6: 5 | O6: 4434 | P6: 5492 | Q6: 611 | R6: =S6 -> 0.087556126 | S6: 0.087556126 | W6: 0_2 | X6: 0 | Y6: 0 | AA6: =+AA5+1 -> 4 | AC6: 8 | AD6: 1.66 | AH6: =AH7-0.08 -> 1.34 | AI6: =+AH6 -> 1.34 | BH6: 0 | BI6: =IF(MOD(BH6*2,2)=1,AVERAGE(BI5,BI7),VLOOKUP(BH6,$BB:$BF,5,FALSE)) -> 0 | BM6: ChanceDFK | BN6: 5754 | BO6: 0.084 | BP6: 0.06 | BQ6: 0.061 | BS6: ChanceDFK | BT6: 54345 | BU6: 0.0596 | BV6: 0.06 | BY6: 3 | BZ6: 6 | CA6: 0 | CB6: 0 | CC6: =CA6/(BZ6+CA6) -> 0 | CD6: 0 | CE6: =CE7-1.5% -> 0.05 | CF6: =CF7-0.025% -> 0.0045 | CH6: =CI6 -> 17 | CI6: 17 | CJ6: 471 | CK6: 283 | CL6: 155 | CM6: 0.62 | CN6: =CL6/(CK6+CL6) -> 0.35388128 | CO6: 0.33 | CQ6: =CR6 -> 14 | CR6: 14 | CS6: 195 | CT6: 620 | CU6: 146 | CV6: 0.76 | CW6: 0.43 | CX6: 0.43 | DA6: -6 | DB6: 0.013 | DD6: =+AVERAGE(DE6,DE7)-0.5 -> -42.5 | DE6: -44 | DF6: 0.473 | DH6: -46 | DI6: =DL6*DN6+DM6*(1-DL6) -> 0.414375 | DJ6: =VLOOKUP(DH6,$DD$5:$DD$24,1,TRUE) -> -46.5 | DK6: =VLOOKUP(DH6,$DD$5:$DD$24,1,TRUE)+4 -> -42.5 | DL6: =(DH6-DJ6)/(DK6-DJ6) -> 0.125 | DM6: =VLOOKUP(DJ6,$DD$5:$DF$24,3,FALSE) -> 0.406 | DN6: =VLOOKUP(DK6,$DD$5:$DF$24,3,FALSE) -> 0.473 | DP6: =DP5+1 -> 3 | DQ6: 0.942 | DR6: =DT6/DP6 -> 1.1166667 | DS6: =$DP6*DQ6 -> 2.826 | DT6: 3.35 | DU6: =DP6&":"&DS6&"," -> 3:2.826, | DX6: =DY6+1.5 -> -26.5 | DY6: -28 | DZ6: 0.31 | EB6: 4.5 | EC6: 1.25 | EE6: -40 | EF6: =EF7-(EF8-EF7) -> 0.20875 | EG6: =VLOOKUP(EE6,$DD$5:$DD$24,1,TRUE) -> -42.5 | EH6: =VLOOKUP(EE6,$DD$5:$DD$24,1,TRUE)+4 -> -38.5 | EI6: =(EE6-EG6)/(EH6-EG6) -> 0.625 | EJ6: =VLOOKUP(EG6,$DX$3:$DZ$19,3,FALSE) -> #N/A | EK6: =VLOOKUP(EH6,$DX$3:$DZ$19,3,FALSE) -> 0.22 | EM6: 4 | EN6: 0.63 | EO6: 0.57 | EP6: 0.54 | EQ6: 0.5 | ES6: =EN16/EN6-1 -> 0.22222222 | ET6: =EO16/EO6-1 -> 0.19298246 | EU6: =EP16/EP6-1 -> 0.35185185 | EV6: =EQ16/EQ6-1 -> 0.58 | EX6: Attack on Wings | FA6: 2 | FB6: 0.001 | FC6: 0.004 | FD6: 0.02 | FE6: 0.03 | FF6: 0.01 | FH6: 7 | FI6: 176 | FJ6: 0.52 | FK6: 1.01 | FL6: 0.94 | FM6: 1.98 | FN6: 18 | FP6: =FP5+1 -> 9 | FQ6: =+FQ5-0.005 -> 0.555 | FS6: 6 | FT6: =FT5+0.025 -> 0.95 | FW6: U | FX6: U | GC6: 6 | GD6: 0.014085177 | GE6: 0.029836417 | GF6: 0.04933168 | GG6: 0.067303006 | GI6: 5 | GJ6: 142 | GK6: 2 | GL6: 0.014084507 | GM6: =+GM2*1.95 -> 0.013079084 | GN6: =+GM6/GM$2 -> 1.95 | GP6: =+ROUND(GP5+1%,2) -> 0.04 | GQ6: =1/(1+GR6) -> 0.25743345 | GR6: =(1/GP6-1)^(1/3) -> 2.8844991 | GS6: 10 | GT6: =+GS6*(1-GQ6)/GQ6 -> 28.844991 | GU6: =+GS6/(GT6+GS6) -> 0.25743345 | GV6: =+GS6^3/(GS6^3+GT6^3) -> 0.04 | GX6: avg xg | GY6: draw % | HA6: gap xg | HB6: adj factor | HD6: 0 | HE6: 0.5
A7: Att - Def | B7: select | D7: PDIM | E7: % stopped | G7: Tactic Skill | H7: select | J7: Matches | K7: Press Events | L7: Event Per Match | N7: 6 | O7: 5497 | P7: 6110 | Q7: 889 | R7: =S7 -> 0.1081951 | S7: 0.1081951 | W7: 0_3 | X7: 0 | Y7: 0 | AA7: =+AA6+1 -> 5 | AC7: 9 | AD7: 1.72 | AH7: =AH8-0.08 -> 1.42 | AI7: =+AH7 -> 1.42 | BB7: 0 | BF7: 0 | BH7: =BH6+1 -> 1 | BI7: =IF(MOD(BH7*2,2)=1,AVERAGE(BI6,BI8),VLOOKUP(BH7,$BB:$BF,5,FALSE)) -> 0.025 | BM7: ChanceIFK | BN7: 2856 | BO7: 0.041 | BP7: 0.041 | BQ7: 0.043 | BS7: ChanceIFK | BT7: 37583 | BU7: 0.0412 | BV7: 0.0415 | BY7: 4 | CC7: =CA7/(BZ7+CA7) -> #DIV/0! | CE7: =CE8-1.5% -> 0.065 | CF7: =CF8-0.025% -> 0.00475 | CH7: =CI7 -> 18 | CI7: 18 | CJ7: 792 | CK7: 440 | CL7: 265 | CM7: 0.64 | CN7: =CL7/(CK7+CL7) -> 0.37588652 | CO7: 0.34 | CQ7: =CR7 -> 15 | CR7: 15 | CS7: 354 | CT7: 1162 | CU7: 274 | CV7: 0.77 | CW7: 0.44 | CX7: =CX6+1% -> 0.44 | DA7: -5 | DB7: 0.034 | DD7: =+AVERAGE(DE7,DE8)-0.5 -> -38.5 | DE7: -40 | DF7: 0.54 | DH7: =DH6+1 -> -45 | DI7: =DL7*DN7+DM7*(1-DL7) -> 0.431125 | DJ7: =VLOOKUP(DH7,$DD$5:$DD$24,1,TRUE) -> -46.5 | DK7: =VLOOKUP(DH7,$DD$5:$DD$24,1,TRUE)+4 -> -42.5 | DL7: =(DH7-DJ7)/(DK7-DJ7) -> 0.375 | DM7: =VLOOKUP(DJ7,$DD$5:$DF$24,3,FALSE) -> 0.406 | DN7: =VLOOKUP(DK7,$DD$5:$DF$24,3,FALSE) -> 0.473 | DP7: =DP6+1 -> 4 | DQ7: 0.925 | DR7: =DT7/DP7 -> 1.1125 | DS7: =$DP7*DQ7 -> 3.7 | DT7: 4.45 | DU7: =DP7&":"&DS7&"," -> 4:3.7, | DX7: =DY7+1.5 -> -22.5 | DY7: -24 | DZ7: 0.34 | EB7: 5 | EC7: 1.2 | EE7: =EE6+1 -> -39 | EF7: =EF8-(EF9-EF8) -> 0.21625 | EG7: =VLOOKUP(EE7,$DD$5:$DD$24,1,TRUE) -> -42.5 | EH7: =VLOOKUP(EE7,$DD$5:$DD$24,1,TRUE)+4 -> -38.5 | EI7: =(EE7-EG7)/(EH7-EG7) -> 0.875 | EJ7: =VLOOKUP(EG7,$DX$3:$DZ$19,3,FALSE) -> #N/A | EK7: =VLOOKUP(EH7,$DX$3:$DZ$19,3,FALSE) -> 0.22 | EM7: 8 | EN7: 0.63 | EO7: 0.59 | EP7: 0.59 | EQ7: 0.54 | ES7: =EN17/EN7-1 -> 0.23809524 | ET7: =EO17/EO7-1 -> 0.13559322 | EU7: =EP17/EP7-1 -> 0.18644068 | EV7: =EQ17/EQ7-1 -> 0.40740741 | EX7: Attack in Middle | FA7: 3 | FB7: 0 | FC7: 0 | FD7: 0.001 | FE7: 0 | FF7: 0 | FH7: 8 | FI7: 193 | FJ7: 0.51 | FK7: 0.96 | FL7: 0.93 | FM7: 1.99 | FN7: 18.9 | FP7: =FP6+1 -> 10 | FQ7: =+FQ6-0.005 -> 0.55 | FS7: 7 | FT7: =FT6+0.025 -> 0.975 | FW7: T | FX7: T | GC7: 6.5 | GD7: 0.01656478 | GE7: 0.03301901 | GF7: 0.056380413 | GG7: 0.071622166 | GI7: 0 | GL7: 0 | GM7: 0 | GP7: =+ROUND(GP6+1%,2) -> 0.05 | GQ7: =1/(1+GR7) -> 0.27259829 | GR7: =(1/GP7-1)^(1/3) -> 2.6684016 | GS7: 10 | GT7: =+GS7*(1-GQ7)/GQ7 -> 26.684016 | GU7: =+GS7/(GT7+GS7) -> 0.27259829 | GV7: =+GS7^3/(GS7^3+GT7^3) -> 0.05 | GX7: 0 | GY7: 0.67883212 | HA7: 0 | HB7: 1.0598356 | HD7: 1 | HE7: 0.53
A8: -99 | B8: 0 | D8: 0 | E8: 0 | G8: 2 | H8: 0 | J8: 3 | K8: 0 | L8: 0 | N8: 7 | O8: 5823 | P8: 5753 | Q8: 1070 | R8: =S8 -> 0.13779883 | S8: 0.13779883 | U8: PNFs | V8: CDs | W8: PNF_CD | X8: freq missed chance | Y8: freq missed chance | AA8: =+AA7+1 -> 6 | AC8: 10 | AD8: 1.77 | AH8: =AH9-0.08 -> 1.5 | AI8: =+AH8 -> 1.5 | BB8: 1 | BF8: =BF9-0.5% -> 0.025 | BH8: =BH7+1 -> 2 | BI8: =IF(MOD(BH8*2,2)=1,AVERAGE(BI7,BI9),VLOOKUP(BH8,$BB:$BF,5,FALSE)) -> 0.03 | BM8: ChanceLeft | BN8: 17864 | BO8: 0.259 | BP8: 0.255 | BQ8: 0.263 | BS8: ChanceLSNonTactic | BT8: 5334 | BU8: 0.0059 | BY8: 5 | BZ8: 20 | CA8: 1 | CB8: 0 | CC8: =CA8/(BZ8+CA8) -> 0.047619048 | CD8: 0 | CE8: =CE9-1.5% -> 0.08 | CF8: =CF9-0.025% -> 0.005 | CH8: =CI8 -> 19 | CI8: 19 | CJ8: 805 | CK8: 531 | CL8: 257 | CM8: 0.6 | CN8: =CL8/(CK8+CL8) -> 0.32614213 | CO8: 0.35 | CQ8: =CR8 -> 16 | CR8: 16 | CS8: 403 | CT8: 1413 | CU8: 338 | CV8: 0.78 | CW8: 0.46 | CX8: =CX7+1% -> 0.45 | DA8: -4 | DB8: 0.068 | DD8: =+AVERAGE(DE8,DE9)-0.5 -> -34.5 | DE8: -36 | DF8: 0.607 | DH8: =DH7+1 -> -44 | DI8: =DL8*DN8+DM8*(1-DL8) -> 0.447875 | DJ8: =VLOOKUP(DH8,$DD$5:$DD$24,1,TRUE) -> -46.5 | DK8: =VLOOKUP(DH8,$DD$5:$DD$24,1,TRUE)+4 -> -42.5 | DL8: =(DH8-DJ8)/(DK8-DJ8) -> 0.625 | DM8: =VLOOKUP(DJ8,$DD$5:$DF$24,3,FALSE) -> 0.406 | DN8: =VLOOKUP(DK8,$DD$5:$DF$24,3,FALSE) -> 0.473 | DP8: =DP7+1 -> 5 | DQ8: 0.906 | DR8: =DT8/DP8 -> 1.11 | DS8: =$DP8*DQ8 -> 4.53 | DT8: 5.55 | DU8: =DP8&":"&DS8&"," -> 5:4.53, | DX8: =DY8+1.5 -> -18.5 | DY8: -20 | DZ8: 0.38 | EB8: 5.5 | EC8: 1.16 | EE8: =EE7+1 -> -38 | EF8: =EI8*EK8+EJ8*(1-EI8) -> 0.22375 | EG8: =VLOOKUP(EE8,$DD$5:$DD$24,1,TRUE) -> -38.5 | EH8: =VLOOKUP(EE8,$DD$5:$DD$24,1,TRUE)+4 -> -34.5 | EI8: =(EE8-EG8)/(EH8-EG8) -> 0.125 | EJ8: =VLOOKUP(EG8,$DX$3:$DZ$19,3,FALSE) -> 0.22 | EK8: =VLOOKUP(EH8,$DX$3:$DZ$19,3,FALSE) -> 0.25 | EM8: 12 | EN8: 0.63 | EO8: 0.65 | EP8: 0.53 | ES8: =EN18/EN8-1 -> 0.20634921 | ET8: =EO18/EO8-1 -> 0.2 | EU8: =EP18/EP8-1 -> 0.47169811 | EV8: =EQ18/EQ8-1 -> #DIV/0! | FA8: Total | FB8: 1 | FC8: 1 | FD8: 1 | FE8: 1 | FF8: 1 | FH8: 9 | FI8: 174 | FJ8: 0.51 | FK8: 0.75 | FL8: 0.72 | FM8: 2.02 | FN8: 19.2 | FP8: =FP7+1 -> 11 | FQ8: =+FQ7-0.005 -> 0.545 | FS8: 8 | FT8: =FT7+0.025 -> 1 | FW8: PNF | FX8: PDIM | GC8: 7 | GD8: 0.017839069 | GE8: 0.035349982 | GF8: 0.059962984 | GG8: 0.078311846 | GP8: =+ROUND(GP7+1%,2) -> 0.06 | GQ8: =1/(1+GR8) -> 0.28553316 | GR8: =(1/GP8-1)^(1/3) -> 2.5022202 | GS8: 10 | GT8: =+GS8*(1-GQ8)/GQ8 -> 25.022202 | GU8: =+GS8/(GT8+GS8) -> 0.28553316 | GV8: =+GS8^3/(GS8^3+GT8^3) -> 0.06 | GX8: 0.75 | GY8: 0.61044177 | HA8: 0.1 | HB8: 1.0532633 | HD8: 2 | HE8: 0.56061153
A9: -29 | B9: 0 | D9: 1 | E9: 0.064653157 | G9: 3 | H9: 0.23404255 | J9: 94 | K9: 22 | L9: 0.23404255 | N9: 8 | O9: 0.16172458 | P9: 0.16172458 | Q9: 0.16172458 | R9: =S9 -> 0.16172458 | S9: 0.16172458 | U9: 1 | V9: 0 | W9: 1_0 | X9: 0.095086403 | Y9: 0.1 | AA9: =+AA8+1 -> 7 | AC9: 11 | AD9: 1.82 | AH9: =AD5 -> 1.58 | AI9: =+AH9 -> 1.58 | AK9: Poss% | AL9: DFK | AM9: PK | AN9: IFK | AO9: SP | AS9: conv | AT9: opp_conv | AU9: Match | AV9: NEventChanceDFK | AW9: Opp_NEventChanceDFK | AX9: N1EventChanceDFK | AY9: Opp_N1EventChanceDFK | BB9: 2 | BF9: =BF10-0.5% -> 0.03 | BH9: =BH8+1 -> 3 | BI9: =IF(MOD(BH9*2,2)=1,AVERAGE(BI8,BI10),VLOOKUP(BH9,$BB:$BF,5,FALSE)) -> 0.035 | BM9: ChanceMid | BN9: 24609 | BO9: 0.357 | BP9: 0.36 | BQ9: 0.371 | BS9: ChanceLeft | BT9: 232106 | BU9: 0.2547 | BV9: 0.2562 | BY9: 6 | BZ9: 26 | CA9: 5 | CB9: 0 | CC9: =CA9/(BZ9+CA9) -> 0.16129032 | CD9: 0 | CE9: =CE10-1.5% -> 0.095 | CF9: =CF10-0.025% -> 0.00525 | CH9: =CI9 -> 20 | CI9: 20 | CJ9: 1242 | CK9: 743 | CL9: 413 | CM9: 0.63 | CN9: =CL9/(CK9+CL9) -> 0.35726644 | CO9: =CO8+1.5% -> 0.365 | CQ9: =CR9 -> 17 | CR9: 17 | CS9: 601 | CT9: 2023 | CU9: 501 | CV9: 0.77 | CW9: 0.45 | CX9: =CX8+1% -> 0.46 | DA9: -3 | DB9: 0.092 | DD9: =+AVERAGE(DE9,DE10)-0.5 -> -30.5 | DE9: -32 | DF9: 0.674 | DH9: =DH8+1 -> -43 | DI9: =DL9*DN9+DM9*(1-DL9) -> 0.464625 | DJ9: =VLOOKUP(DH9,$DD$5:$DD$24,1,TRUE) -> -46.5 | DK9: =VLOOKUP(DH9,$DD$5:$DD$24,1,TRUE)+4 -> -42.5 | DL9: =(DH9-DJ9)/(DK9-DJ9) -> 0.875 | DM9: =VLOOKUP(DJ9,$DD$5:$DF$24,3,FALSE) -> 0.406 | DN9: =VLOOKUP(DK9,$DD$5:$DF$24,3,FALSE) -> 0.473 | DP9: =DP8+1 -> 6 | DQ9: 0.888 | DR9: =DT9/DP9 -> 1.1083333 | DS9: =$DP9*DQ9 -> 5.328 | DT9: 6.65 | DU9: =DP9&":"&DS9&"," -> 6:5.328, | DX9: =DY9+1.5 -> -14.5 | DY9: -16 | DZ9: 0.41 | EB9: 6 | EC9: 1.13 | EE9: =EE8+1 -> -37 | EF9: =EI9*EK9+EJ9*(1-EI9) -> 0.23125 | EG9: =VLOOKUP(EE9,$DD$5:$DD$24,1,TRUE) -> -38.5 | EH9: =VLOOKUP(EE9,$DD$5:$DD$24,1,TRUE)+4 -> -34.5 | EI9: =(EE9-EG9)/(EH9-EG9) -> 0.375 | EJ9: =VLOOKUP(EG9,$DX$3:$DZ$19,3,FALSE) -> 0.22 | EK9: =VLOOKUP(EH9,$DX$3:$DZ$19,3,FALSE) -> 0.25 | FA9: % match | FB9: 0.1 | FC9: 0.53 | FD9: 0.25 | FE9: 0.12 | FF9: 1 | FH9: 10 | FI9: 107 | FJ9: 0.54 | FK9: 0.88 | FL9: 0.74 | FM9: 1.79 | FN9: 19.8 | FP9: =FP8+1 -> 12 | FQ9: =+FQ8-0.005 -> 0.54 | FS9: 9 | FT9: =FT8+0.025 -> 1.025 | GC9: 7.5 | GD9: 0.018879799 | GE9: 0.037731658 | GF9: 0.062813647 | GG9: 0.079141863 | GP9: =+ROUND(GP8+1%,2) -> 0.07 | GQ9: =1/(1+GR9) -> 0.29687369 | GR9: =(1/GP9-1)^(1/3) -> 2.3684359 | GS9: 10 | GT9: =+GS9*(1-GQ9)/GQ9 -> 23.684359 | GU9: =+GS9/(GT9+GS9) -> 0.29687369 | GV9: =+GS9^3/(GS9^3+GT9^3) -> 0.07 | GX9: 1 | GY9: 0.55282555 | HA9: 0.2 | HB9: 1.0465657 | HD9: 3 | HE9: 0.59909763
A10: -28 | B10: 0 | D10: 2 | E10: 0.097225318 | G10: 4 | H10: 0.68370884 | J10: 1154 | K10: 789 | L10: 0.68370884 | N10: 9 | O10: 6376 | P10: 5875 | Q10: 1443 | R10: =S10 -> 0.18375408 | S10: 0.18375408 | U10: 1 | V10: 1 | W10: 1_1 | X10: 0.064030648 | Y10: 0 | AA10: 8 | AC10: 12 | AD10: 1.8616769 | AH10: =AD6 -> 1.66 | AI10: =+AH10 -> 1.66 | AK10: 0-4% | AL10: 0.27705628 | AM10: 0.0086580087 | AN10: 0.11255411 | AO10: 0.3982684 | AR10: 0 | AS10: 0.23186528 | AT10: 0.45161921 | AU10: 64268 | AV10: 3860 | AW10: 15347 | AX10: 895 | AY10: 6931 | BB10: 3 | BF10: =BF11-0.5% -> 0.035 | BH10: =BH9+1 -> 4 | BI10: =IF(MOD(BH10*2,2)=1,AVERAGE(BI9,BI11),VLOOKUP(BH10,$BB:$BF,5,FALSE)) -> 0.04 | BM10: ChanceRight | BN10: 17806 | BO10: 0.258 | BP10: 0.255 | BQ10: 0.263 | BS10: ChanceMid | BT10: 327717 | BU10: 0.3596 | BV10: 0.3617 | BY10: 7 | BZ10: 82 | CA10: 5 | CB10: 0 | CC10: =CA10/(BZ10+CA10) -> 0.057471264 | CD10: 0 | CE10: =CE11-1.5% -> 0.11 | CF10: =CF11-0.025% -> 0.0055 | CH10: =CI10 -> 21 | CI10: 21 | CJ10: 1636 | CK10: 980 | CL10: 552 | CM10: 0.63 | CN10: =CL10/(CK10+CL10) -> 0.36031332 | CO10: =CO9+0.5% -> 0.37 | CQ10: =CR10 -> 18 | CR10: 18 | CS10: 818 | CT10: 2953 | CU10: 703 | CV10: 0.78 | CW10: 0.46 | CX10: =CX9+1% -> 0.47 | DA10: -2 | DB10: 0.147 | DD10: =+AVERAGE(DE10,DE11)-0.5 -> -26.5 | DE10: -28 | DF10: 0.741 | DH10: =DH9+1 -> -42 | DI10: =DL10*DN10+DM10*(1-DL10) -> 0.481375 | DJ10: =VLOOKUP(DH10,$DD$5:$DD$24,1,TRUE) -> -42.5 | DK10: =VLOOKUP(DH10,$DD$5:$DD$24,1,TRUE)+4 -> -38.5 | DL10: =(DH10-DJ10)/(DK10-DJ10) -> 0.125 | DM10: =VLOOKUP(DJ10,$DD$5:$DF$24,3,FALSE) -> 0.473 | DN10: =VLOOKUP(DK10,$DD$5:$DF$24,3,FALSE) -> 0.54 | DP10: =DP9+1 -> 7 | DQ10: 0.87 | DR10: =DT10/DP10 -> 1.1071429 | DS10: =$DP10*DQ10 -> 6.09 | DT10: 7.75 | DU10: =DP10&":"&DS10&"," -> 7:6.09, | DX10: =DY10+1.5 -> -10.5 | DY10: -12 | DZ10: 0.45 | EB10: 6.5 | EC10: 1.1 | EE10: =EE9+1 -> -36 | EF10: =EI10*EK10+EJ10*(1-EI10) -> 0.23875 | EG10: =VLOOKUP(EE10,$DD$5:$DD$24,1,TRUE) -> -38.5 | EH10: =VLOOKUP(EE10,$DD$5:$DD$24,1,TRUE)+4 -> -34.5 | EI10: =(EE10-EG10)/(EH10-EG10) -> 0.625 | EJ10: =VLOOKUP(EG10,$DX$3:$DZ$19,3,FALSE) -> 0.22 | EK10: =VLOOKUP(EH10,$DX$3:$DZ$19,3,FALSE) -> 0.25 | FA10: Freq% | FB10: 0.042 | FC10: 0.097 | FD10: 0.203 | FE10: 0.292 | FF10: 0.141 | FH10: 11+ | FI10: 125 | FJ10: 0.55 | FK10: 0.82 | FL10: 0.66 | FM10: 1.73 | FN10: 19.8 | FP10: =FP9+1 -> 13 | FQ10: =+FQ9-0.005 -> 0.535 | FS10: 10 | FT10: =FT9+0.025 -> 1.05 | GC10: 8 | GD10: 0.020027799 | GE10: 0.039994423 | GF10: 0.067048928 | GG10: 0.0827701 | GP10: =+ROUND(GP9+1%,2) -> 0.08 | GQ10: =1/(1+GR10) -> 0.30701416 | GR10: =(1/GP10-1)^(1/3) -> 2.2571787 | GS10: 10 | GT10: =+GS10*(1-GQ10)/GQ10 -> 22.571787 | GU10: =+GS10/(GT10+GS10) -> 0.30701416 | GV10: =+GS10^3/(GS10^3+GT10^3) -> 0.08 | GX10: 1.25 | GY10: 0.46581197 | HA10: 0.3 | HB10: 1.0397369 | HD10: 4 | HE10: 0.63577779
A11: -27 | B11: 0 | D11: 3 | E11: 0.13100437 | G11: 5 | H11: 1.1436902 | J11: 4287 | K11: 4903 | L11: 1.1436902 | N11: 10 | O11: 7680 | P11: 6394 | Q11: 1971 | R11: =S11 -> 0.22631744 | S11: 0.22631744 | U11: 1 | V11: 2 | W11: 1_2 | X11: 0.030925732 | Y11: 0 | AA11: =+AA10+1 -> 9 | AB11: 1.7480793 | AC11: 13 | AD11: 1.9 | AH11: =AD7 -> 1.72 | AI11: =+AH11 -> 1.72 | AK11: 5-9% | AL11: 0.081367521 | AM11: 0.025982906 | AN11: 0.069059829 | AO11: 0.17641026 | AR11: 5 | AS11: 0.24151858 | AT11: 0.42438988 | AU11: 62180 | AV11: 4952 | AW11: 13358 | AX11: 1196 | AY11: 5669 | BB11: 4 | BF11: =BF12-0.5% -> 0.04 | BH11: =BH10+1 -> 5 | BI11: =IF(MOD(BH11*2,2)=1,AVERAGE(BI10,BI12),VLOOKUP(BH11,$BB:$BF,5,FALSE)) -> 0.045 | BM11: ChancePK | BP11: 0.024 | BS11: ChancePK | BT11: 21919 | BU11: 0.0241 | BV11: 0.0242 | BY11: 8 | BZ11: 129 | CA11: 13 | CB11: 1 | CC11: =CA11/(BZ11+CA11) -> 0.091549296 | CD11: 0.008 | CE11: =CE12-1.5% -> 0.125 | CF11: =CF12-0.025% -> 0.00575 | CH11: =CI11 -> 22 | CI11: 22 | CJ11: 2091 | CK11: 1169 | CL11: 709 | CM11: 0.64 | CN11: =CL11/(CK11+CL11) -> 0.37752929 | CO11: =CO10+0.5% -> 0.375 | CQ11: =CR11 -> 19 | CR11: 19 | CS11: 787 | CT11: 2951 | CU11: 742 | CV11: 0.79 | CW11: 0.49 | CX11: =CX10+1% -> 0.48 | DA11: -1 | DB11: 0.25 | DD11: =+AVERAGE(DE11,DE12)-0.5 -> -22.5 | DE11: -24 | DF11: 0.806 | DH11: =DH10+1 -> -41 | DI11: =DL11*DN11+DM11*(1-DL11) -> 0.498125 | DJ11: =VLOOKUP(DH11,$DD$5:$DD$24,1,TRUE) -> -42.5 | DK11: =VLOOKUP(DH11,$DD$5:$DD$24,1,TRUE)+4 -> -38.5 | DL11: =(DH11-DJ11)/(DK11-DJ11) -> 0.375 | DM11: =VLOOKUP(DJ11,$DD$5:$DF$24,3,FALSE) -> 0.473 | DN11: =VLOOKUP(DK11,$DD$5:$DF$24,3,FALSE) -> 0.54 | DP11: =DP10+1 -> 8 | DQ11: 0.852 | DR11: =DT11/DP11 -> 1.10625 | DS11: =$DP11*DQ11 -> 6.816 | DT11: 8.85 | DU11: =DP11&":"&DS11&"," -> 8:6.816, | DX11: =DY11+1.5 -> -6.5 | DY11: -8 | DZ11: 0.49 | EB11: 7 | EC11: 1.06 | EE11: =EE10+1 -> -35 | EF11: =EI11*EK11+EJ11*(1-EI11) -> 0.24625 | EG11: =VLOOKUP(EE11,$DD$5:$DD$24,1,TRUE) -> -38.5 | EH11: =VLOOKUP(EE11,$DD$5:$DD$24,1,TRUE)+4 -> -34.5 | EI11: =(EE11-EG11)/(EH11-EG11) -> 0.875 | EJ11: =VLOOKUP(EG11,$DX$3:$DZ$19,3,FALSE) -> 0.22 | EK11: =VLOOKUP(EH11,$DX$3:$DZ$19,3,FALSE) -> 0.25 | FP11: =FP10+1 -> 14 | FQ11: =+FQ10-0.005 -> 0.53 | FS11: 11 | FT11: =FT10+0.025 -> 1.075 | GC11: 8.5 | GD11: 0.020784709 | GE11: 0.040727835 | GF11: 0.067526746 | GG11: 0.083507307 | GP11: =+ROUND(GP10+1%,2) -> 0.09 | GQ11: =1/(1+GR11) -> 0.31621706 | GR11: =(1/GP11-1)^(1/3) -> 2.1623847 | GS11: 10 | GT11: =+GS11*(1-GQ11)/GQ11 -> 21.623847 | GU11: =+GS11/(GT11+GS11) -> 0.31621706 | GV11: =+GS11^3/(GS11^3+GT11^3) -> 0.09 | GX11: 1.5 | GY11: 0.45127119 | HA11: 0.4 | HB11: 1.0327709 | HD11: 5 | HE11: 0.66609573
A12: -26 | B12: 0.00025641026 | G12: 6 | H12: 1.4091013 | J12: 4373 | K12: 6162 | L12: 1.4091013 | N12: 11 | O12: 7841 | P12: 5891 | Q12: 2293 | R12: =S12 -> 0.25664063 | S12: 0.25664063 | U12: 1 | V12: 3 | W12: 1_3 | X12: 0.016020392 | Y12: 0 | AA12: =+AA11+1 -> 10 | AB12: 1.7878602 | AC12: 14 | AD12: 1.93 | AH12: =AD8 -> 1.77 | AI12: =+AH12 -> 1.77 | AK12: 10-14% | AL12: 0.054788419 | AM12: 0.028062361 | AN12: 0.056792873 | AO12: 0.13964365 | AR12: 10 | AS12: 0.27333293 | AT12: 0.41195577 | AU12: 154200 | AV12: 16511 | AW12: 30479 | AX12: 4513 | AY12: 12556 | BB12: 5 | BF12: =BF13-0.5% -> 0.045 | BH12: =BH11+1 -> 6 | BI12: =IF(MOD(BH12*2,2)=1,AVERAGE(BI11,BI13),VLOOKUP(BH12,$BB:$BF,5,FALSE)) -> 0.05 | BS12: ChanceRight | BT12: 232339 | BU12: 0.2549 | BV12: 0.2564 | BY12: 9 | BZ12: 85 | CA12: 15 | CB12: 0 | CC12: =CA12/(BZ12+CA12) -> 0.15 | CD12: 0 | CE12: 0.14 | CF12: =CF13-0.025% -> 0.006 | CH12: =CI12 -> 23 | CI12: 23 | CJ12: 1932 | CK12: 1104 | CL12: 673 | CM12: 0.64 | CN12: =CL12/(CK12+CL12) -> 0.37872819 | CO12: =CO11+0.5% -> 0.38 | CQ12: =CR12 -> 20 | CR12: 20 | CS12: 945 | CT12: 3645 | CU12: 941 | CV12: 0.79 | CW12: 0.5 | CX12: =CX11+1% -> 0.49 | DA12: 0 | DB12: 0.438 | DD12: =+AVERAGE(DE12,DE13)-0.5 -> -18.5 | DE12: -20 | DF12: 0.901 | DH12: =DH11+1 -> -40 | DI12: =DL12*DN12+DM12*(1-DL12) -> 0.514875 | DJ12: =VLOOKUP(DH12,$DD$5:$DD$24,1,TRUE) -> -42.5 | DK12: =VLOOKUP(DH12,$DD$5:$DD$24,1,TRUE)+4 -> -38.5 | DL12: =(DH12-DJ12)/(DK12-DJ12) -> 0.625 | DM12: =VLOOKUP(DJ12,$DD$5:$DF$24,3,FALSE) -> 0.473 | DN12: =VLOOKUP(DK12,$DD$5:$DF$24,3,FALSE) -> 0.54 | DP12: =DP11+1 -> 9 | DQ12: 0.834 | DR12: =DT12/DP12 -> 1.1055556 | DS12: =$DP12*DQ12 -> 7.506 | DT12: 9.95 | DU12: =DP12&":"&DS12&"," -> 9:7.506, | DX12: =DY12+1.5 -> -2.5 | DY12: -4 | DZ12: 0.52 | EB12: 7.5 | EC12: 1.02 | EE12: =EE11+1 -> -34 | EF12: =EI12*EK12+EJ12*(1-EI12) -> 0.25375 | EG12: =VLOOKUP(EE12,$DD$5:$DD$24,1,TRUE) -> -34.5 | EH12: =VLOOKUP(EE12,$DD$5:$DD$24,1,TRUE)+4 -> -30.5 | EI12: =(EE12-EG12)/(EH12-EG12) -> 0.125 | EJ12: =VLOOKUP(EG12,$DX$3:$DZ$19,3,FALSE) -> 0.25 | EK12: =VLOOKUP(EH12,$DX$3:$DZ$19,3,FALSE) -> 0.28 | FH12: S Tactic Skill | FI12: Match | FJ12: Press% | FK12: Freq LS Press | FL12: Freq Long Shot | FM12: Avg Points LS Team | FN12: Avg Press Tactic Skill | FP12: =FP11+1 -> 15 | FQ12: =+FQ11-0.005 -> 0.525 | FS12: 12 | FT12: =FT11+0.025 -> 1.1 | GC12: 9 | GD12: 0.01929225 | GE12: 0.041551934 | GF12: 0.070504798 | GG12: 0.086744639 | GP12: =+ROUND(GP11+1%,2) -> 0.1 | GQ12: =1/(1+GR12) -> 0.32466649 | GR12: =(1/GP12-1)^(1/3) -> 2.0800838 | GS12: 10 | GT12: =+GS12*(1-GQ12)/GQ12 -> 20.800838 | GU12: =+GS12/(GT12+GS12) -> 0.32466649 | GV12: =+GS12^3/(GS12^3+GT12^3) -> 0.1 | GX12: 1.75 | GY12: 0.33914729 | HA12: 0.5 | HB12: 1.025661 | HD12: 6 | HE12: 0.7008637
